Workbook

Sheet Jun2026_Settled
A1: KXHMONTH-26JUN — “Will June 2026 be the hottest June ever?” | SETTLED NO · full post-mortem & model scorecard
A2: RESULT: NOAA printed 1.09 for June 2026 · the 1.18 record (June 2024) stood · YES settled worthless, NO paid $1.00
A3: Observed days k | C3: ERA5 June mean | E3: Model P(YES) | G3: Predicted NOAA | I3: ACTUAL NOAA | K3: Residual | M3: OUTCOME
A4: =$C$83 | C4: =$C$89 | E4: =$C$100 | G4: =$C$94 | I4: =$C$166 | K4: =$C$167 | M4: =$C$174
A5: This is the SETTLED June market, filled with real data end-to-end: 30 observed ERA5 days, the archived ECMWF run, the live Kalshi price path, and the actual account fills. Same template as the August workbook.
A6: BLOCK 1 — SETTLEMENT & TRANSLATION CONSTANTS (settlement constants hard-coded; translation regressed live from Block 7)
A7: Contract (Kalshi ticker) | C7: KXHMONTH-26JUN
A8: Exchange | C8: Kalshi (CFTC-regulated DCM)
A9: Settlement oracle | C9: NOAA NCEI ‘Climate at a Glance’ — GLOBAL land+ocean monthly anomaly
A10: NOAA baseline | C10: 1901–2000 (settlement baseline)
A11: ERA5 baseline | C11: 1991–2020 (deterministic offset — absorbed by the OLS, not signal)
A12: Quantity | C12: Global, cos-latitude-weighted 2 m temperature MONTHLY MEAN
A13: Days in month (D) | C13: 30
A15: Settlement thresholds
A16: June record (printed) | C16: 1.18 | E16: June 2024 (NOAA). This record STOOD.
A17: Latent threshold (YES iff latent ≥) | C17: 1.185 | E17: Printed had to be ≥1.19. It printed 1.09 — never close.
A18: Tie-band low (latent) | C18: 1.175 | E18: Latent 1.175–1.185 would print 1.18 → tie → settles NO.
A19: Tie clause | C19: NONE — a printed tie (1.18) settles NO
A21: ERA5 → NOAA June translation (computed live from Block 7)
A22: a (intercept) | C22: =INTERCEPT($C$243:$C$278,$B$243:$B$278) | E22: formula: INTERCEPT(NOAA_Jun, ERA5_Jun) over Block 7
A23: b (slope) | C23: =SLOPE($C$243:$C$278,$B$243:$B$278) | E23: formula: SLOPE(...) — absorbs the deterministic baseline offset
A24: σ_translation (residual) | C24: =STEYX($C$243:$C$278,$B$243:$B$278) | E24: formula: STEYX(...) — irreducible translation scatter
A25: n (years in fit) | C25: =COUNT($B$243:$B$278)
A26: K_threshold on ERA5 scale = (latent−a)/b | C26: =($C$17-$C$22)/$C$23
A28: Variance collapse — σ_NOAA by observed-day count k (empirical; slower than 1/√(days left) because regimes persist)
A29: k (observed days) | C29: sd_f (ERA5 scale) | D29: ref (offline) | E29: σ_NOAA
A30: 2 | C30: =IFERROR(INDEX(LINEST($B$243:$B$278,$E$243:$F$278),3,2),$D$30) | D30: 0.0738 | E30: =IFERROR(SQRT(($C$23*$C$30)^2+$C$24^2),"") | G30: sd_f = LINEST std-error of ERA5_Jun ~ ERA5_May + Jun_first-k · σ_NOAA = √((b·sd_f)²+σ_trans²)
A31: 5 | C31: =IFERROR(INDEX(LINEST($B$243:$B$278,$G$243:$H$278),3,2),$D$31) | D31: 0.0697 | E31: =IFERROR(SQRT(($C$23*$C$31)^2+$C$24^2),"") | G31: ‘ref (offline)’ = same regression computed outside Excel from the same rows; used only if LINEST is unavailable.
A32: 10 | C32: =IFERROR(INDEX(LINEST($B$243:$B$278,$I$243:$J$278),3,2),$D$32) | D32: 0.0535 | E32: =IFERROR(SQRT(($C$23*$C$32)^2+$C$24^2),"")
A33: 15 | C33: =IFERROR(INDEX(LINEST($B$243:$B$278,$K$243:$L$278),3,2),$D$33) | D33: 0.0387 | E33: =IFERROR(SQRT(($C$23*$C$33)^2+$C$24^2),"")
A34: 20 | C34: =IFERROR(INDEX(LINEST($B$243:$B$278,$M$243:$N$278),3,2),$D$34) | D34: 0.0271 | E34: =IFERROR(SQRT(($C$23*$C$34)^2+$C$24^2),"")
A35: 25 | C35: =IFERROR(INDEX(LINEST($B$243:$B$278,$O$243:$P$278),3,2),$D$35) | D35: 0.0152 | E35: =IFERROR(SQRT(($C$23*$C$35)^2+$C$24^2),"")
A36: 30 | C36: 0 | D36: 0 | E36: =IFERROR(SQRT(($C$23*$C$36)^2+$C$24^2),"") | G36: k=30: month fully observed → forecast error 0 by definition
A38: External indices & model settings
A39: ONI (CPC, AMJ 2026) | C39: 1 | E39: El Niño ramping through the June window.
A40: GISTEMP June record (printed) | C40: 1.24 | E40: NASA GISTEMP — Polymarket oracle (different dataset & baseline).
A41: GISTEMP latent threshold | C41: 1.235 | E41: Polymarket brackets: ties count INTO the bracket.
A42: GISTEMP a / b / σ | C42: 0.5839 | E42: 0.9482 | G42: 0.0474 | I42: OLS GISTEMP_Jun ~ ERA5_Jun, n=36.
A43: GISTEMP June 2026 actual | C43: 1.18 | E43: ⚠ From project notes (CLAUDE.md), NOT in the local gistemp.txt vintage (ends 05/2026). Verify at NASA before relying on it.
A44: ρ forecast-error correlation mix | C44: 0.6 | E44: Pipeline convention. Irrelevant here (0 remaining days) but kept for template parity.
...

Sheet ENS_members_raw
A1: 51-MEMBER ENSEMBLE — DEGENERATE (month complete)
A2: June is fully observed (k=30). There are no remaining days to forecast, so every member's full-month ERA5 estimate equals the realised mean. The spread collapsing to zero is CORRECT here, not a placeholder.
A3: No 51-member June archive exists locally (ens_spread.py output begins with July), and none is needed at k=30.
A5: Member # | B5: Full-Jun ERA5 mean °C | C5: μ_NOAA | D5: σ_member | E5: P(YES) member | F5: Central breach? | G5: μ_GISTEMP | H5: P(YES) GIS member
A6: 1 | B6: 0.5593 | C6: =IF(ISNUMBER($B6),'Jun2026_Settled'!$C$22+'Jun2026_Settled'!$C$23*$B6,"") | D6: =IF(ISNUMBER($B6),IFERROR(SQRT(('Jun2026_Settled'!$C$23*'Jun2026_Settled'!$C$93)^2+'Jun2026_Settled'!$C$24^2),""),"") | E6: =IF(OR($C6="",$D6="",$D6=0),"",1-NORMSDIST(('Jun2026_Settled'!$C$17-$C6)/$D6)) | F6: =IF(ISNUMBER($B6),IF($B6>='Jun2026_Settled'!$C$26,1,0),"") | G6: =IF(ISNUMBER($B6),'Jun2026_Settled'!$C$42+'Jun2026_Settled'!$E$42*$B6,"") | H6: =IFERROR(IF(OR($G6="",'Jun2026_Settled'!$C$93=""),"",1-NORMSDIST(('Jun2026_Settled'!$C$41-$G6)/SQRT(('Jun2026_Settled'!$E$42*'Jun2026_Settled'!$C$93)^2+'Jun2026_Settled'!$G$42^2))),"")
A7: 2 | B7: 0.5593 | C7: =IF(ISNUMBER($B7),'Jun2026_Settled'!$C$22+'Jun2026_Settled'!$C$23*$B7,"") | D7: =IF(ISNUMBER($B7),IFERROR(SQRT(('Jun2026_Settled'!$C$23*'Jun2026_Settled'!$C$93)^2+'Jun2026_Settled'!$C$24^2),""),"") | E7: =IF(OR($C7="",$D7="",$D7=0),"",1-NORMSDIST(('Jun2026_Settled'!$C$17-$C7)/$D7)) | F7: =IF(ISNUMBER($B7),IF($B7>='Jun2026_Settled'!$C$26,1,0),"") | G7: =IF(ISNUMBER($B7),'Jun2026_Settled'!$C$42+'Jun2026_Settled'!$E$42*$B7,"") | H7: =IFERROR(IF(OR($G7="",'Jun2026_Settled'!$C$93=""),"",1-NORMSDIST(('Jun2026_Settled'!$C$41-$G7)/SQRT(('Jun2026_Settled'!$E$42*'Jun2026_Settled'!$C$93)^2+'Jun2026_Settled'!$G$42^2))),"")
A8: 3 | B8: 0.5593 | C8: =IF(ISNUMBER($B8),'Jun2026_Settled'!$C$22+'Jun2026_Settled'!$C$23*$B8,"") | D8: =IF(ISNUMBER($B8),IFERROR(SQRT(('Jun2026_Settled'!$C$23*'Jun2026_Settled'!$C$93)^2+'Jun2026_Settled'!$C$24^2),""),"") | E8: =IF(OR($C8="",$D8="",$D8=0),"",1-NORMSDIST(('Jun2026_Settled'!$C$17-$C8)/$D8)) | F8: =IF(ISNUMBER($B8),IF($B8>='Jun2026_Settled'!$C$26,1,0),"") | G8: =IF(ISNUMBER($B8),'Jun2026_Settled'!$C$42+'Jun2026_Settled'!$E$42*$B8,"") | H8: =IFERROR(IF(OR($G8="",'Jun2026_Settled'!$C$93=""),"",1-NORMSDIST(('Jun2026_Settled'!$C$41-$G8)/SQRT(('Jun2026_Settled'!$E$42*'Jun2026_Settled'!$C$93)^2+'Jun2026_Settled'!$G$42^2))),"")
A9: 4 | B9: 0.5593 | C9: =IF(ISNUMBER($B9),'Jun2026_Settled'!$C$22+'Jun2026_Settled'!$C$23*$B9,"") | D9: =IF(ISNUMBER($B9),IFERROR(SQRT(('Jun2026_Settled'!$C$23*'Jun2026_Settled'!$C$93)^2+'Jun2026_Settled'!$C$24^2),""),"") | E9: =IF(OR($C9="",$D9="",$D9=0),"",1-NORMSDIST(('Jun2026_Settled'!$C$17-$C9)/$D9)) | F9: =IF(ISNUMBER($B9),IF($B9>='Jun2026_Settled'!$C$26,1,0),"") | G9: =IF(ISNUMBER($B9),'Jun2026_Settled'!$C$42+'Jun2026_Settled'!$E$42*$B9,"") | H9: =IFERROR(IF(OR($G9="",'Jun2026_Settled'!$C$93=""),"",1-NORMSDIST(('Jun2026_Settled'!$C$41-$G9)/SQRT(('Jun2026_Settled'!$E$42*'Jun2026_Settled'!$C$93)^2+'Jun2026_Settled'!$G$42^2))),"")
A10: 5 | B10: 0.5593 | C10: =IF(ISNUMBER($B10),'Jun2026_Settled'!$C$22+'Jun2026_Settled'!$C$23*$B10,"") | D10: =IF(ISNUMBER($B10),IFERROR(SQRT(('Jun2026_Settled'!$C$23*'Jun2026_Settled'!$C$93)^2+'Jun2026_Settled'!$C$24^2),""),"") | E10: =IF(OR($C10="",$D10="",$D10=0),"",1-NORMSDIST(('Jun2026_Settled'!$C$17-$C10)/$D10)) | F10: =IF(ISNUMBER($B10),IF($B10>='Jun2026_Settled'!$C$26,1,0),"") | G10: =IF(ISNUMBER($B10),'Jun2026_Settled'!$C$42+'Jun2026_Settled'!$E$42*$B10,"") | H10: =IFERROR(IF(OR($G10="",'Jun2026_Settled'!$C$93=""),"",1-NORMSDIST(('Jun2026_Settled'!$C$41-$G10)/SQRT(('Jun2026_Settled'!$E$42*'Jun2026_Settled'!$C$93)^2+'Jun2026_Settled'!$G$42^2))),"")
A11: 6 | B11: 0.5593 | C11: =IF(ISNUMBER($B11),'Jun2026_Settled'!$C$22+'Jun2026_Settled'!$C$23*$B11,"") | D11: =IF(ISNUMBER($B11),IFERROR(SQRT(('Jun2026_Settled'!$C$23*'Jun2026_Settled'!$C$93)^2+'Jun2026_Settled'!$C$24^2),""),"") | E11: =IF(OR($C11="",$D11="",$D11=0),"",1-NORMSDIST(('Jun2026_Settled'!$C$17-$C11)/$D11)) | F11: =IF(ISNUMBER($B11),IF($B11>='Jun2026_Settled'!$C$26,1,0),"") | G11: =IF(ISNUMBER($B11),'Jun2026_Settled'!$C$42+'Jun2026_Settled'!$E$42*$B11,"") | H11: =IFERROR(IF(OR($G11="",'Jun2026_Settled'!$C$93=""),"",1-NORMSDIST(('Jun2026_Settled'!$C$41-$G11)/SQRT(('Jun2026_Settled'!$E$42*'Jun2026_Settled'!$C$93)^2+'Jun2026_Settled'!$G$42^2))),"")
A12: 7 | B12: 0.5593 | C12: =IF(ISNUMBER($B12),'Jun2026_Settled'!$C$22+'Jun2026_Settled'!$C$23*$B12,"") | D12: =IF(ISNUMBER($B12),IFERROR(SQRT(('Jun2026_Settled'!$C$23*'Jun2026_Settled'!$C$93)^2+'Jun2026_Settled'!$C$24^2),""),"") | E12: =IF(OR($C12="",$D12="",$D12=0),"",1-NORMSDIST(('Jun2026_Settled'!$C$17-$C12)/$D12)) | F12: =IF(ISNUMBER($B12),IF($B12>='Jun2026_Settled'!$C$26,1,0),"") | G12: =IF(ISNUMBER($B12),'Jun2026_Settled'!$C$42+'Jun2026_Settled'!$E$42*$B12,"") | H12: =IFERROR(IF(OR($G12="",'Jun2026_Settled'!$C$93=""),"",1-NORMSDIST(('Jun2026_Settled'!$C$41-$G12)/SQRT(('Jun2026_Settled'!$E$42*'Jun2026_Settled'!$C$93)^2+'Jun2026_Settled'!$G$42^2))),"")
A13: 8 | B13: 0.5593 | C13: =IF(ISNUMBER($B13),'Jun2026_Settled'!$C$22+'Jun2026_Settled'!$C$23*$B13,"") | D13: =IF(ISNUMBER($B13),IFERROR(SQRT(('Jun2026_Settled'!$C$23*'Jun2026_Settled'!$C$93)^2+'Jun2026_Settled'!$C$24^2),""),"") | E13: =IF(OR($C13="",$D13="",$D13=0),"",1-NORMSDIST(('Jun2026_Settled'!$C$17-$C13)/$D13)) | F13: =IF(ISNUMBER($B13),IF($B13>='Jun2026_Settled'!$C$26,1,0),"") | G13: =IF(ISNUMBER($B13),'Jun2026_Settled'!$C$42+'Jun2026_Settled'!$E$42*$B13,"") | H13: =IFERROR(IF(OR($G13="",'Jun2026_Settled'!$C$93=""),"",1-NORMSDIST(('Jun2026_Settled'!$C$41-$G13)/SQRT(('Jun2026_Settled'!$E$42*'Jun2026_Settled'!$C$93)^2+'Jun2026_Settled'!$G$42^2))),"")
A14: 9 | B14: 0.5593 | C14: =IF(ISNUMBER($B14),'Jun2026_Settled'!$C$22+'Jun2026_Settled'!$C$23*$B14,"") | D14: =IF(ISNUMBER($B14),IFERROR(SQRT(('Jun2026_Settled'!$C$23*'Jun2026_Settled'!$C$93)^2+'Jun2026_Settled'!$C$24^2),""),"") | E14: =IF(OR($C14="",$D14="",$D14=0),"",1-NORMSDIST(('Jun2026_Settled'!$C$17-$C14)/$D14)) | F14: =IF(ISNUMBER($B14),IF($B14>='Jun2026_Settled'!$C$26,1,0),"") | G14: =IF(ISNUMBER($B14),'Jun2026_Settled'!$C$42+'Jun2026_Settled'!$E$42*$B14,"") | H14: =IFERROR(IF(OR($G14="",'Jun2026_Settled'!$C$93=""),"",1-NORMSDIST(('Jun2026_Settled'!$C$41-$G14)/SQRT(('Jun2026_Settled'!$E$42*'Jun2026_Settled'!$C$93)^2+'Jun2026_Settled'!$G$42^2))),"")
A15: 10 | B15: 0.5593 | C15: =IF(ISNUMBER($B15),'Jun2026_Settled'!$C$22+'Jun2026_Settled'!$C$23*$B15,"") | D15: =IF(ISNUMBER($B15),IFERROR(SQRT(('Jun2026_Settled'!$C$23*'Jun2026_Settled'!$C$93)^2+'Jun2026_Settled'!$C$24^2),""),"") | E15: =IF(OR($C15="",$D15="",$D15=0),"",1-NORMSDIST(('Jun2026_Settled'!$C$17-$C15)/$D15)) | F15: =IF(ISNUMBER($B15),IF($B15>='Jun2026_Settled'!$C$26,1,0),"") | G15: =IF(ISNUMBER($B15),'Jun2026_Settled'!$C$42+'Jun2026_Settled'!$E$42*$B15,"") | H15: =IFERROR(IF(OR($G15="",'Jun2026_Settled'!$C$93=""),"",1-NORMSDIST(('Jun2026_Settled'!$C$41-$G15)/SQRT(('Jun2026_Settled'!$E$42*'Jun2026_Settled'!$C$93)^2+'Jun2026_Settled'!$G$42^2))),"")
A16: 11 | B16: 0.5593 | C16: =IF(ISNUMBER($B16),'Jun2026_Settled'!$C$22+'Jun2026_Settled'!$C$23*$B16,"") | D16: =IF(ISNUMBER($B16),IFERROR(SQRT(('Jun2026_Settled'!$C$23*'Jun2026_Settled'!$C$93)^2+'Jun2026_Settled'!$C$24^2),""),"") | E16: =IF(OR($C16="",$D16="",$D16=0),"",1-NORMSDIST(('Jun2026_Settled'!$C$17-$C16)/$D16)) | F16: =IF(ISNUMBER($B16),IF($B16>='Jun2026_Settled'!$C$26,1,0),"") | G16: =IF(ISNUMBER($B16),'Jun2026_Settled'!$C$42+'Jun2026_Settled'!$E$42*$B16,"") | H16: =IFERROR(IF(OR($G16="",'Jun2026_Settled'!$C$93=""),"",1-NORMSDIST(('Jun2026_Settled'!$C$41-$G16)/SQRT(('Jun2026_Settled'!$E$42*'Jun2026_Settled'!$C$93)^2+'Jun2026_Settled'!$G$42^2))),"")
A17: 12 | B17: 0.5593 | C17: =IF(ISNUMBER($B17),'Jun2026_Settled'!$C$22+'Jun2026_Settled'!$C$23*$B17,"") | D17: =IF(ISNUMBER($B17),IFERROR(SQRT(('Jun2026_Settled'!$C$23*'Jun2026_Settled'!$C$93)^2+'Jun2026_Settled'!$C$24^2),""),"") | E17: =IF(OR($C17="",$D17="",$D17=0),"",1-NORMSDIST(('Jun2026_Settled'!$C$17-$C17)/$D17)) | F17: =IF(ISNUMBER($B17),IF($B17>='Jun2026_Settled'!$C$26,1,0),"") | G17: =IF(ISNUMBER($B17),'Jun2026_Settled'!$C$42+'Jun2026_Settled'!$E$42*$B17,"") | H17: =IFERROR(IF(OR($G17="",'Jun2026_Settled'!$C$93=""),"",1-NORMSDIST(('Jun2026_Settled'!$C$41-$G17)/SQRT(('Jun2026_Settled'!$E$42*'Jun2026_Settled'!$C$93)^2+'Jun2026_Settled'!$G$42^2))),"")
... A56: 51 | B56: 0.5593 | C56: =IF(ISNUMBER($B56),'Jun2026_Settled'!$C$22+'Jun2026_Settled'!$C$23*$B56,"") | D56: =IF(ISNUMBER($B56),IFERROR(SQRT(('Jun2026_Settled'!$C$23*'Jun2026_Settled'!$C$93)^2+'Jun2026_Settled'!$C$24^2),""),"") | E56: =IF(OR($C56="",$D56="",$D56=0),"",1-NORMSDIST(('Jun2026_Settled'!$C$17-$C56)/$D56)) | F56: =IF(ISNUMBER($B56),IF($B56>='Jun2026_Settled'!$C$26,1,0),"") | G56: =IF(ISNUMBER($B56),'Jun2026_Settled'!$C$42+'Jun2026_Settled'!$E$42*$B56,"") | H56: =IFERROR(IF(OR($G56="",'Jun2026_Settled'!$C$93=""),"",1-NORMSDIST(('Jun2026_Settled'!$C$41-$G56)/SQRT(('Jun2026_Settled'!$E$42*'Jun2026_Settled'!$C$93)^2+'Jun2026_Settled'!$G$42^2))),"")
A58: Members loaded | B58: =COUNT($B$6:$B$56)
A59: Median member ERA5 | B59: =IFERROR(MEDIAN($B$6:$B$56),"")
A60: Member spread σ (zero by construction) | B60: =IFERROR(STDEV($B$6:$B$56),"")
A61: Members breaching the record | B61: =IFERROR(SUM($F$6:$F$56),"")
A64: P(YES) ENSEMBLE — NOAA ▶ headline | E64: =IFERROR(AVERAGE($E$6:$E$56),"") | G64: P(YES) GISTEMP ▶ | H64: =IFERROR(AVERAGE($H$6:$H$56),"")
A66: Member-average of per-member tail probabilities. With zero remaining uncertainty this equals the single-path Normal value — as it must.

Sheet Fcst_log
A1: FORECAST-RUN LOG — June (retrospective; per-run archive unavailable)
A2: The live forecast_log only begins 2026-07-09, so June has no run-by-run history. The single row below records the ONE archived retrieval used to fill the daily ECMWF column.
A3: In a live month this tab is the lead-time edge: a rising remaining-days mean is an early buy-YES signal; a price spike with no new high here is a fade signal.
A5: Pulled (UTC) | B5: Model | C5: Run cycle | D5: Remaining-days mean anomaly °C | E5: Δ vs prior same model | F5: Signal | G5: Note
A6: 2026-07-25 (retrospective) | B6: ECMWF-arch | C6: archive | D6: 0.628 | F6: =IF($E6="","",IF($E6>0.03,"▲ SURGE ENTERING",IF($E6<-0.03,"▼ COOLING","flat"))) | G6: Open-Meteo Historical-Forecast API, 15° cos-weighted grid, whole-month mean. Short lead — not a true multi-day forecast.
E7: =IF($D7="","",IFERROR($D7-LOOKUP(2,1/($B$6:$B6=$B7),$D$6:$D6),"")) | F7: =IF($E7="","",IF($E7>0.03,"▲ SURGE ENTERING",IF($E7<-0.03,"▼ COOLING","flat")))
E8: =IF($D8="","",IFERROR($D8-LOOKUP(2,1/($B$6:$B7=$B8),$D$6:$D7),"")) | F8: =IF($E8="","",IF($E8>0.03,"▲ SURGE ENTERING",IF($E8<-0.03,"▼ COOLING","flat")))
E9: =IF($D9="","",IFERROR($D9-LOOKUP(2,1/($B$6:$B8=$B9),$D$6:$D8),"")) | F9: =IF($E9="","",IF($E9>0.03,"▲ SURGE ENTERING",IF($E9<-0.03,"▼ COOLING","flat")))
E10: =IF($D10="","",IFERROR($D10-LOOKUP(2,1/($B$6:$B9=$B10),$D$6:$D9),"")) | F10: =IF($E10="","",IF($E10>0.03,"▲ SURGE ENTERING",IF($E10<-0.03,"▼ COOLING","flat")))
E11: =IF($D11="","",IFERROR($D11-LOOKUP(2,1/($B$6:$B10=$B11),$D$6:$D10),"")) | F11: =IF($E11="","",IF($E11>0.03,"▲ SURGE ENTERING",IF($E11<-0.03,"▼ COOLING","flat")))
E12: =IF($D12="","",IFERROR($D12-LOOKUP(2,1/($B$6:$B11=$B12),$D$6:$D11),"")) | F12: =IF($E12="","",IF($E12>0.03,"▲ SURGE ENTERING",IF($E12<-0.03,"▼ COOLING","flat")))
E13: =IF($D13="","",IFERROR($D13-LOOKUP(2,1/($B$6:$B12=$B13),$D$6:$D12),"")) | F13: =IF($E13="","",IF($E13>0.03,"▲ SURGE ENTERING",IF($E13<-0.03,"▼ COOLING","flat")))
E14: =IF($D14="","",IFERROR($D14-LOOKUP(2,1/($B$6:$B13=$B14),$D$6:$D13),"")) | F14: =IF($E14="","",IF($E14>0.03,"▲ SURGE ENTERING",IF($E14<-0.03,"▼ COOLING","flat")))
E15: =IF($D15="","",IFERROR($D15-LOOKUP(2,1/($B$6:$B14=$B15),$D$6:$D14),"")) | F15: =IF($E15="","",IF($E15>0.03,"▲ SURGE ENTERING",IF($E15<-0.03,"▼ COOLING","flat")))
E16: =IF($D16="","",IFERROR($D16-LOOKUP(2,1/($B$6:$B15=$B16),$D$6:$D15),"")) | F16: =IF($E16="","",IF($E16>0.03,"▲ SURGE ENTERING",IF($E16<-0.03,"▼ COOLING","flat")))
E17: =IF($D17="","",IFERROR($D17-LOOKUP(2,1/($B$6:$B16=$B17),$D$6:$D16),"")) | F17: =IF($E17="","",IF($E17>0.03,"▲ SURGE ENTERING",IF($E17<-0.03,"▼ COOLING","flat")))
E18: =IF($D18="","",IFERROR($D18-LOOKUP(2,1/($B$6:$B17=$B18),$D$6:$D17),"")) | F18: =IF($E18="","",IF($E18>0.03,"▲ SURGE ENTERING",IF($E18<-0.03,"▼ COOLING","flat")))
... E125: =IF($D125="","",IFERROR($D125-LOOKUP(2,1/($B$6:$B124=$B125),$D$6:$D124),"")) | F125: =IF($E125="","",IF($E125>0.03,"▲ SURGE ENTERING",IF($E125<-0.03,"▼ COOLING","flat")))
