Workbook

Sheet Jun_2026
A1: KXHMONTH-26JUN — “Will June 2026 be the hottest June ever?”
A2: Settlement thresholds | E2: Variance σ_NOAA | J2: Ensemble | K2: P(Yes) | L2: μ_GISTEMP | M2: MARKET & PROFITABILITY
A3: June record (printed) | C3: 1.18 | E3: k (observed days) | F3: sd_f (ERA5 scale) | G3: ref (offline) | H3: σ_NOAA | J3: Mean | K3: =IF(ISNUMBER($N20),IF($N20>=Jun_2026!$C$9,1,0),"") | L3: =IF(ISNUMBER($N20),Jun_2026!$C$14+Jun_2026!$D$14*$N20,"") | M3: NO (results)
A4: Needed | C4: 1.185 | E4: 2 | F4: =IFERROR(INDEX(LINEST($B$57:$B$73,$E$57:$F$73),3,2),$G$4) -> 0.0738 | G4: 0.0738 | H4: =IFERROR(SQRT(($C$6*$F$4)^2+$C$7^2),"") -> 0.068763395 | J4: Hottest | K4: =IF(ISNUMBER($N21),IF($N21>=Jun_2026!$C$9,1,0),"") | L4: =IF(ISNUMBER($N21),Jun_2026!$C$14+Jun_2026!$D$14*$N21,"") | M4: NO contracts bought | Q4: =IFERROR(AVERAGE(#REF!),"")
A5: a (intercept) | C5: =INTERCEPT($C$57:$C$73,$B$57:$B$73) -> 0.62637623 | E5: 10 | F5: =IFERROR(INDEX(LINEST($B$57:$B$73,$I$57:$J$73),3,2),$G$5) -> 0.0535 | G5: 0.0535 | H5: =IFERROR(SQRT(($C$6*$F$5)^2+$C$7^2),"") -> 0.054939087 | J5: Coldest | K5: =IF(ISNUMBER($N22),IF($N22>=Jun_2026!$C$9,1,0),"") | L5: =IF(ISNUMBER($N22),Jun_2026!$C$14+Jun_2026!$D$14*$N22,"") | M5: YES (results)
A6: b (slope) | C6: =SLOPE($C$57:$C$73,$B$57:$B$73) -> 0.81348338 | E6: 15 | F6: =IFERROR(INDEX(LINEST($B$57:$B$73,$K$57:$L$73),3,2),$G$6) -> 0.0387 | G6: 0.0387 | H6: =IFERROR(SQRT(($C$6*$F$6)^2+$C$7^2),"") -> 0.045992376 | J6: Tie (1.18) | K6: =IF(ISNUMBER($N23),IF($N23>=Jun_2026!$C$9,1,0),"") | L6: =IF(ISNUMBER($N23),Jun_2026!$C$14+Jun_2026!$D$14*$N23,"") | M6: YES contracts bought
A7: σ_translation (residual) | C7: =STEYX($C$57:$C$73,$B$57:$B$73) -> 0.03352901 | E7: 20 | F7: =IFERROR(INDEX(LINEST($B$57:$B$73,$M$57:$N$73),3,2),$G$7) -> 0.0271 | G7: 0.0271 | H7: =IFERROR(SQRT(($C$6*$F$7)^2+$C$7^2),"") -> 0.040127224 | J7: dev3 (last 3 days) | M7: Fees paid
A8: n (years in fit) | C8: =COUNT($B$57:$B$73) -> 17 | E8: 25 | F8: =IFERROR(INDEX(LINEST($B$57:$B$73,$O$59:$P$73),3,2),$G$8) -> 0.0152 | G8: 0.0152 | H8: =IFERROR(SQRT(($C$6*$F$8)^2+$C$7^2),"") -> 0.035736346 | M8: Settlement (Yes or NO)
A9: K_threshold on ERA5 scale | C9: =($C$4-$C$5)/$C$6 -> 0.68670582 | E9: 30 | F9: 0 | G9: 0 | H9: =IFERROR(SQRT(($C$6*$F$9)^2+$C$7^2),"") -> 0.03352901 | M9: Settlement payout (Yes or NO)
A10: Regression Expectation | M10: REALISED P&L
A11: ONI (CPC, AMJ 2026) | C11: 1 | E11: k — observed days | F11: =COUNT($B$20:$B$49) -> 30 | M11: ROI
A12: GISTEMP June record (printed) | C12: 1.24 | E12: Banked mean B_k | G12: =IF($R$1=0,"",#REF!/$R$1)
A13: GISTEMP latent threshold | C13: 1.235 | E13: Remaining days
A14: GISTEMP a / b / σ | C14: 0.5839 | D14: 0.9482
A15: ρ forecast-error correlation mix | C15: 0.6
A16: 5-yr mean ERA5 | C16: =AVERAGE($B$69:$B$73) -> 0.44098
A18: DAILY TABLE
A19: Date | B19: ERA5 °C (Actual) | C19: Expectation | D19: BIAS | E19: Needed to beat | F19: YES close (¢) | G19: Volume | I19: 2024 - 2nd | J19: 2023 - 1st
A20: May 28 | B20: 0.536 | C20: 0.6625 | D20: 0.6625 | F20: 10 | G20: 51
A21: May 29 | B21: 0.567 | C21: 0.7454 | D21: 0.7454 | F21: 10 | G21: 10
A22: May 30 | B22: 0.608 | C22: 0.687 | D22: 0.687 | F22: 28 | G22: 1003.06
A23: May 31 | B23: 0.611 | C23: 0.5874 | D23: 0.5874 | F23: 21 | G23: 285.61
A24: Jun 01 | B24: 0.605 | C24: 0.6847 | D24: 0.6847 | F24: 15 | G24: 302.5
A25: Jun 02 | B25: 0.651 | C25: 0.7047 | D25: 0.7047 | F25: 13 | G25: 240.81
A26: Jun 03 | B26: 0.653 | C26: 0.8007 | D26: 0.8007 | F26: 13 | G26: 21
A27: Jun 04 | B27: 0.646 | C27: 0.7268 | D27: 0.7268 | F27: 15 | G27: 27.22
A28: Jun 05 | B28: 0.607 | C28: 0.6995 | D28: 0.6995 | F28: 15 | G28: 720.73
A29: Jun 06 | B29: 0.596 | C29: 0.8535 | D29: 0.8535 | F29: 13 | G29: 280.5
A30: Jun 07 | B30: 0.622 | C30: 0.7588 | D30: 0.7588 | F30: 12 | G30: 296.2
A31: Jun 08 | B31: 0.6 | C31: 0.7158 | D31: 0.7158 | F31: 10 | G31: 15.9
... A53: Jun 30 | B53: 0.635 | C53: 0.635 | D53: 0.635 | F53: 3 | G53: 1818.51
A55: CALIBRATION AUDIT: June history 1990–2025
A56: Year | B56: ERA5 Jun mean | C56: NOAA Jun
A57: 2009 | B57: 0.0054 | C57: 0.67
A58: 2010 | B58: 0.0876 | C58: 0.68
A59: 2011 | B59: 0.0214 | C59: 0.6
A60: 2012 | B60: 0.1205 | C60: 0.68
A61: 2013 | B61: 0.1084 | C61: 0.7
A62: 2014 | B62: 0.0732 | C62: 0.71
A63: 2015 | B63: 0.1873 | C63: 0.83
...

Sheet Jul_2026

Sheet Aug_2026

Sheet Sep_2026
