Workbook

Sheet Aug2026_Live
A1: KXHMONTH-26AUG — “Will August 2026 be the hottest August ever?”
A2: LIVE SUMMARY (auto-updates as you fill the daily table)
A3: Observed days k | C3: MTD mean °C | E3: P(YES) ensemble | G3: Market YES ask | I3: Edge (best side) | K3: dev3 | M3: ACTION
A4: =$C$83 -> 0 | C4: =$C$85 | E4: =$C$100 | G4: =IF($C$105="","",$C$105) | I4: =IF(AND($C$118="",$C$119=""),"",MAX(IF($C$118="",-99,$C$118),IF($C$119="",-99,$C$119))) | K4: =$C$147 | M4: =$C$134 -> — fill daily table + ENS members —
A5: HOW TO USE: fill ONLY the yellow cells (daily table cols B–J, ENS members col B, market prices). Everything else is a live formula. Full legend: Block 8 at the bottom.
A6: BLOCK 1 — SETTLEMENT & TRANSLATION CONSTANTS (settlement constants are the only hard-coded numbers; everything else computes)
A9: Settlement oracle | C9: NOAA NCEI ‘Climate at a Glance’ — GLOBAL land+ocean monthly anomaly
A10: NOAA baseline | C10: 1901–2000 (settlement baseline)
A11: ERA5 baseline | C11: 1991–2020 (offset is DETERMINISTIC — absorbed by the OLS below, not signal)
A12: Quantity | C12: Global, cos-latitude-weighted 2 m temperature MONTHLY MEAN (never per-station)
A13: Days in month (D) | C13: 31
A15: Settlement thresholds
A16: August record (printed) | C16: 1.25 | E16: Aug 2023 (NOAA, live vintage). 2024=1.24, 2025=1.07.
A17: Latent threshold (YES iff latent ≥) | C17: 1.255 | E17: Printed must be ≥1.26. Rounding: printed 1.26 ⇔ latent ≥1.255.
A18: Tie-band low (latent) | C18: 1.245 | E18: Latent 1.245–1.255 prints 1.25 → settles NO (tailwind for NO).
A19: Tie clause | C19: NONE — a printed tie (1.25) settles NO
A21: ERA5 → NOAA August translation (computed live from Block 7 audit trail)
A22: a (intercept) | C22: =INTERCEPT($C$163:$C$198,$B$163:$B$198) -> 0.58921188 | E22: formula: INTERCEPT(NOAA_Aug, ERA5_Aug) over Block 7
A23: b (slope) | C23: =SLOPE($C$163:$C$198,$B$163:$B$198) -> 0.96190198 | E23: formula: SLOPE(...) — absorbs the deterministic baseline offset
A24: σ_translation (residual) | C24: =STEYX($C$163:$C$198,$B$163:$B$198) -> 0.0356756 | E24: formula: STEYX(...) — irreducible translation scatter, never shrinks
A25: n (years in fit) | C25: =COUNT($B$163:$B$198) -> 36
A26: K_threshold on ERA5 scale = (latent−a)/b | C26: =($C$17-$C$22)/$C$23 -> 0.69215797 | E26: ERA5-scale value the month must reach
A28: Variance collapse — σ_NOAA by observed-day count k (empirical; collapses slower than 1/√(days left) because regimes persist)
A29: k (observed days) | C29: sd_f (ERA5 scale) | D29: ref (offline) | E29: σ_NOAA
A30: 2 | C30: =IFERROR(INDEX(LINEST($B$163:$B$198,$E$163:$F$198),3,2),$D$30) -> 0.0569 | D30: 0.0569 | E30: =IFERROR(SQRT(($C$23*$C$30)^2+$C$24^2),"") -> 0.065332722 | G30: sd_f = LINEST std-error of ERA5_Aug ~ ERA5_Jul + Aug_first-k · σ_NOAA = √((b·sd_f)²+σ_trans²)
A31: 5 | C31: =IFERROR(INDEX(LINEST($B$163:$B$198,$G$163:$H$198),3,2),$D$31) -> 0.0541 | D31: 0.0541 | E31: =IFERROR(SQRT(($C$23*$C$31)^2+$C$24^2),"") -> 0.063093544 | G31: ‘ref (offline)’ = the same regression computed from the same Block-7 rows outside Excel. sd_f uses LINEST and falls back to ref only if LINEST is unavailable — the two must agree.
A32: 10 | C32: =IFERROR(INDEX(LINEST($B$163:$B$198,$I$163:$J$198),3,2),$D$32) -> 0.0432 | D32: 0.0432 | E32: =IFERROR(SQRT(($C$23*$C$32)^2+$C$24^2),"") -> 0.054767665
A33: 15 | C33: =IFERROR(INDEX(LINEST($B$163:$B$198,$K$163:$L$198),3,2),$D$33) -> 0.0415 | D33: 0.0415 | E33: =IFERROR(SQRT(($C$23*$C$33)^2+$C$24^2),"") -> 0.053537553
A34: 20 | C34: =IFERROR(INDEX(LINEST($B$163:$B$198,$M$163:$N$198),3,2),$D$34) -> 0.0387 | D34: 0.0387 | E34: =IFERROR(SQRT(($C$23*$C$34)^2+$C$24^2),"") -> 0.051560588
A35: 25 | C35: =IFERROR(INDEX(LINEST($B$163:$B$198,$O$163:$P$198),3,2),$D$35) -> 0.0222 | D35: 0.0222 | E35: =IFERROR(SQRT(($C$23*$C$35)^2+$C$24^2),"") -> 0.041578256
A36: 31 | C36: 0 | D36: 0 | E36: =IFERROR(SQRT(($C$23*$C$36)^2+$C$24^2),"") -> 0.0356756 | G36: k=31: month fully observed → forecast error is 0 by definition
A38: External indices & model settings
A39: ONI (CPC, latest season) | C39: 1 | E39: AMJ 2026 = +1.0 (El Niño ramping). Update monthly; records cluster in El Niño.
A40: GISTEMP August record (printed) | C40: 1.3 | E40: NASA GISTEMP, Aug 2024 — Polymarket oracle (different dataset, ~+0.09 vs NOAA).
A41: GISTEMP latent threshold | C41: 1.295 | E41: Polymarket brackets: ties count INTO the bracket → latent ≥ record−0.005.
A42: GISTEMP a / b / σ | C42: 0.5803 | E42: 1.0288 | G42: 0.0542 | I42: OLS GISTEMP_Aug ~ ERA5_Aug, n=36 (1990–2025).
A43: ρ forecast-error correlation mix | C43: 0.6 | E43: Pipeline convention (update_data.py). Days are NOT independent — ρ>0 keeps σ honest.
A44: Climatology reference (5-yr mean ERA5 Aug) | C44: =AVERAGE($B$194:$B$198) -> 0.5045 | E44: Benchmark for forecast skill in Block 5.
A46: BLOCK 2 — DAILY TABLE (Aug 1–31) — the spine. BLANK until real data arrives; nothing is simulated.
A48: Date | B48: ERA5 obs anomaly °C | C48: status | D48: ECMWF ENS mean °C | E48: ENS spread σ °C | F48: ENS min | G48: ENS max | H48: GFS °C | I48: GEFS mean °C | J48: GEFS σ | K48: USED (obs→fcst) | L48: Running MTD (banked) | M48: Err ENS (obs−fcst) | N48: Err GFS | O48: Err GEFS | P48: fcst for remaining | Q48: |e|ENS | R48: e²ENS | S48: |e|GFS | T48: e²GFS | U48: |e|GEFS | V48: e²GEFS | W48: (obs−clim)² | X48: ENS σ remaining
...

Sheet ENS_members_raw
A1: 51-MEMBER ECMWF IFS ENS — the honest core of P(YES)
A2: Paste each member's FULL-AUGUST ERA5-mean estimate into column B (from ens_spread.py → member_july_mean_era5 equivalent for August). Everything else computes.
A3: WHY members, not one path: a point estimate near a threshold LIES. The member spread carries the real tail mass (July 2026: a deterministic 0.0% hid a true ~25%).
A5: Member # | B5: Full-Aug ERA5 mean °C (INPUT) | C5: μ_NOAA | D5: σ_member | E5: P(YES) member | F5: Central breach? | G5: μ_GISTEMP | H5: P(YES) GIS member
A6: 1 | C6: =IF(ISNUMBER($B6),Aug2026_Live!$C$22+Aug2026_Live!$C$23*$B6,"") | D6: =IF(ISNUMBER($B6),IFERROR(SQRT((Aug2026_Live!$C$23*Aug2026_Live!$C$93)^2+Aug2026_Live!$C$24^2),""),"") | E6: =IF(OR($C6="",$D6="",$D6=0),"",1-NORMSDIST((Aug2026_Live!$C$17-$C6)/$D6)) | F6: =IF(ISNUMBER($B6),IF($B6>=Aug2026_Live!$C$26,1,0),"") | G6: =IF(ISNUMBER($B6),Aug2026_Live!$C$42+Aug2026_Live!$E$42*$B6,"") | H6: =IFERROR(IF(OR($G6="",Aug2026_Live!$C$93=""),"",1-NORMSDIST((Aug2026_Live!$C$41-$G6)/SQRT((Aug2026_Live!$E$42*Aug2026_Live!$C$93)^2+Aug2026_Live!$G$42^2))),"")
A7: 2 | C7: =IF(ISNUMBER($B7),Aug2026_Live!$C$22+Aug2026_Live!$C$23*$B7,"") | D7: =IF(ISNUMBER($B7),IFERROR(SQRT((Aug2026_Live!$C$23*Aug2026_Live!$C$93)^2+Aug2026_Live!$C$24^2),""),"") | E7: =IF(OR($C7="",$D7="",$D7=0),"",1-NORMSDIST((Aug2026_Live!$C$17-$C7)/$D7)) | F7: =IF(ISNUMBER($B7),IF($B7>=Aug2026_Live!$C$26,1,0),"") | G7: =IF(ISNUMBER($B7),Aug2026_Live!$C$42+Aug2026_Live!$E$42*$B7,"") | H7: =IFERROR(IF(OR($G7="",Aug2026_Live!$C$93=""),"",1-NORMSDIST((Aug2026_Live!$C$41-$G7)/SQRT((Aug2026_Live!$E$42*Aug2026_Live!$C$93)^2+Aug2026_Live!$G$42^2))),"")
A8: 3 | C8: =IF(ISNUMBER($B8),Aug2026_Live!$C$22+Aug2026_Live!$C$23*$B8,"") | D8: =IF(ISNUMBER($B8),IFERROR(SQRT((Aug2026_Live!$C$23*Aug2026_Live!$C$93)^2+Aug2026_Live!$C$24^2),""),"") | E8: =IF(OR($C8="",$D8="",$D8=0),"",1-NORMSDIST((Aug2026_Live!$C$17-$C8)/$D8)) | F8: =IF(ISNUMBER($B8),IF($B8>=Aug2026_Live!$C$26,1,0),"") | G8: =IF(ISNUMBER($B8),Aug2026_Live!$C$42+Aug2026_Live!$E$42*$B8,"") | H8: =IFERROR(IF(OR($G8="",Aug2026_Live!$C$93=""),"",1-NORMSDIST((Aug2026_Live!$C$41-$G8)/SQRT((Aug2026_Live!$E$42*Aug2026_Live!$C$93)^2+Aug2026_Live!$G$42^2))),"")
A9: 4 | C9: =IF(ISNUMBER($B9),Aug2026_Live!$C$22+Aug2026_Live!$C$23*$B9,"") | D9: =IF(ISNUMBER($B9),IFERROR(SQRT((Aug2026_Live!$C$23*Aug2026_Live!$C$93)^2+Aug2026_Live!$C$24^2),""),"") | E9: =IF(OR($C9="",$D9="",$D9=0),"",1-NORMSDIST((Aug2026_Live!$C$17-$C9)/$D9)) | F9: =IF(ISNUMBER($B9),IF($B9>=Aug2026_Live!$C$26,1,0),"") | G9: =IF(ISNUMBER($B9),Aug2026_Live!$C$42+Aug2026_Live!$E$42*$B9,"") | H9: =IFERROR(IF(OR($G9="",Aug2026_Live!$C$93=""),"",1-NORMSDIST((Aug2026_Live!$C$41-$G9)/SQRT((Aug2026_Live!$E$42*Aug2026_Live!$C$93)^2+Aug2026_Live!$G$42^2))),"")
A10: 5 | C10: =IF(ISNUMBER($B10),Aug2026_Live!$C$22+Aug2026_Live!$C$23*$B10,"") | D10: =IF(ISNUMBER($B10),IFERROR(SQRT((Aug2026_Live!$C$23*Aug2026_Live!$C$93)^2+Aug2026_Live!$C$24^2),""),"") | E10: =IF(OR($C10="",$D10="",$D10=0),"",1-NORMSDIST((Aug2026_Live!$C$17-$C10)/$D10)) | F10: =IF(ISNUMBER($B10),IF($B10>=Aug2026_Live!$C$26,1,0),"") | G10: =IF(ISNUMBER($B10),Aug2026_Live!$C$42+Aug2026_Live!$E$42*$B10,"") | H10: =IFERROR(IF(OR($G10="",Aug2026_Live!$C$93=""),"",1-NORMSDIST((Aug2026_Live!$C$41-$G10)/SQRT((Aug2026_Live!$E$42*Aug2026_Live!$C$93)^2+Aug2026_Live!$G$42^2))),"")
A11: 6 | C11: =IF(ISNUMBER($B11),Aug2026_Live!$C$22+Aug2026_Live!$C$23*$B11,"") | D11: =IF(ISNUMBER($B11),IFERROR(SQRT((Aug2026_Live!$C$23*Aug2026_Live!$C$93)^2+Aug2026_Live!$C$24^2),""),"") | E11: =IF(OR($C11="",$D11="",$D11=0),"",1-NORMSDIST((Aug2026_Live!$C$17-$C11)/$D11)) | F11: =IF(ISNUMBER($B11),IF($B11>=Aug2026_Live!$C$26,1,0),"") | G11: =IF(ISNUMBER($B11),Aug2026_Live!$C$42+Aug2026_Live!$E$42*$B11,"") | H11: =IFERROR(IF(OR($G11="",Aug2026_Live!$C$93=""),"",1-NORMSDIST((Aug2026_Live!$C$41-$G11)/SQRT((Aug2026_Live!$E$42*Aug2026_Live!$C$93)^2+Aug2026_Live!$G$42^2))),"")
A12: 7 | C12: =IF(ISNUMBER($B12),Aug2026_Live!$C$22+Aug2026_Live!$C$23*$B12,"") | D12: =IF(ISNUMBER($B12),IFERROR(SQRT((Aug2026_Live!$C$23*Aug2026_Live!$C$93)^2+Aug2026_Live!$C$24^2),""),"") | E12: =IF(OR($C12="",$D12="",$D12=0),"",1-NORMSDIST((Aug2026_Live!$C$17-$C12)/$D12)) | F12: =IF(ISNUMBER($B12),IF($B12>=Aug2026_Live!$C$26,1,0),"") | G12: =IF(ISNUMBER($B12),Aug2026_Live!$C$42+Aug2026_Live!$E$42*$B12,"") | H12: =IFERROR(IF(OR($G12="",Aug2026_Live!$C$93=""),"",1-NORMSDIST((Aug2026_Live!$C$41-$G12)/SQRT((Aug2026_Live!$E$42*Aug2026_Live!$C$93)^2+Aug2026_Live!$G$42^2))),"")
A13: 8 | C13: =IF(ISNUMBER($B13),Aug2026_Live!$C$22+Aug2026_Live!$C$23*$B13,"") | D13: =IF(ISNUMBER($B13),IFERROR(SQRT((Aug2026_Live!$C$23*Aug2026_Live!$C$93)^2+Aug2026_Live!$C$24^2),""),"") | E13: =IF(OR($C13="",$D13="",$D13=0),"",1-NORMSDIST((Aug2026_Live!$C$17-$C13)/$D13)) | F13: =IF(ISNUMBER($B13),IF($B13>=Aug2026_Live!$C$26,1,0),"") | G13: =IF(ISNUMBER($B13),Aug2026_Live!$C$42+Aug2026_Live!$E$42*$B13,"") | H13: =IFERROR(IF(OR($G13="",Aug2026_Live!$C$93=""),"",1-NORMSDIST((Aug2026_Live!$C$41-$G13)/SQRT((Aug2026_Live!$E$42*Aug2026_Live!$C$93)^2+Aug2026_Live!$G$42^2))),"")
A14: 9 | C14: =IF(ISNUMBER($B14),Aug2026_Live!$C$22+Aug2026_Live!$C$23*$B14,"") | D14: =IF(ISNUMBER($B14),IFERROR(SQRT((Aug2026_Live!$C$23*Aug2026_Live!$C$93)^2+Aug2026_Live!$C$24^2),""),"") | E14: =IF(OR($C14="",$D14="",$D14=0),"",1-NORMSDIST((Aug2026_Live!$C$17-$C14)/$D14)) | F14: =IF(ISNUMBER($B14),IF($B14>=Aug2026_Live!$C$26,1,0),"") | G14: =IF(ISNUMBER($B14),Aug2026_Live!$C$42+Aug2026_Live!$E$42*$B14,"") | H14: =IFERROR(IF(OR($G14="",Aug2026_Live!$C$93=""),"",1-NORMSDIST((Aug2026_Live!$C$41-$G14)/SQRT((Aug2026_Live!$E$42*Aug2026_Live!$C$93)^2+Aug2026_Live!$G$42^2))),"")
A15: 10 | C15: =IF(ISNUMBER($B15),Aug2026_Live!$C$22+Aug2026_Live!$C$23*$B15,"") | D15: =IF(ISNUMBER($B15),IFERROR(SQRT((Aug2026_Live!$C$23*Aug2026_Live!$C$93)^2+Aug2026_Live!$C$24^2),""),"") | E15: =IF(OR($C15="",$D15="",$D15=0),"",1-NORMSDIST((Aug2026_Live!$C$17-$C15)/$D15)) | F15: =IF(ISNUMBER($B15),IF($B15>=Aug2026_Live!$C$26,1,0),"") | G15: =IF(ISNUMBER($B15),Aug2026_Live!$C$42+Aug2026_Live!$E$42*$B15,"") | H15: =IFERROR(IF(OR($G15="",Aug2026_Live!$C$93=""),"",1-NORMSDIST((Aug2026_Live!$C$41-$G15)/SQRT((Aug2026_Live!$E$42*Aug2026_Live!$C$93)^2+Aug2026_Live!$G$42^2))),"")
A16: 11 | C16: =IF(ISNUMBER($B16),Aug2026_Live!$C$22+Aug2026_Live!$C$23*$B16,"") | D16: =IF(ISNUMBER($B16),IFERROR(SQRT((Aug2026_Live!$C$23*Aug2026_Live!$C$93)^2+Aug2026_Live!$C$24^2),""),"") | E16: =IF(OR($C16="",$D16="",$D16=0),"",1-NORMSDIST((Aug2026_Live!$C$17-$C16)/$D16)) | F16: =IF(ISNUMBER($B16),IF($B16>=Aug2026_Live!$C$26,1,0),"") | G16: =IF(ISNUMBER($B16),Aug2026_Live!$C$42+Aug2026_Live!$E$42*$B16,"") | H16: =IFERROR(IF(OR($G16="",Aug2026_Live!$C$93=""),"",1-NORMSDIST((Aug2026_Live!$C$41-$G16)/SQRT((Aug2026_Live!$E$42*Aug2026_Live!$C$93)^2+Aug2026_Live!$G$42^2))),"")
A17: 12 | C17: =IF(ISNUMBER($B17),Aug2026_Live!$C$22+Aug2026_Live!$C$23*$B17,"") | D17: =IF(ISNUMBER($B17),IFERROR(SQRT((Aug2026_Live!$C$23*Aug2026_Live!$C$93)^2+Aug2026_Live!$C$24^2),""),"") | E17: =IF(OR($C17="",$D17="",$D17=0),"",1-NORMSDIST((Aug2026_Live!$C$17-$C17)/$D17)) | F17: =IF(ISNUMBER($B17),IF($B17>=Aug2026_Live!$C$26,1,0),"") | G17: =IF(ISNUMBER($B17),Aug2026_Live!$C$42+Aug2026_Live!$E$42*$B17,"") | H17: =IFERROR(IF(OR($G17="",Aug2026_Live!$C$93=""),"",1-NORMSDIST((Aug2026_Live!$C$41-$G17)/SQRT((Aug2026_Live!$E$42*Aug2026_Live!$C$93)^2+Aug2026_Live!$G$42^2))),"")
... A56: 51 | C56: =IF(ISNUMBER($B56),Aug2026_Live!$C$22+Aug2026_Live!$C$23*$B56,"") | D56: =IF(ISNUMBER($B56),IFERROR(SQRT((Aug2026_Live!$C$23*Aug2026_Live!$C$93)^2+Aug2026_Live!$C$24^2),""),"") | E56: =IF(OR($C56="",$D56="",$D56=0),"",1-NORMSDIST((Aug2026_Live!$C$17-$C56)/$D56)) | F56: =IF(ISNUMBER($B56),IF($B56>=Aug2026_Live!$C$26,1,0),"") | G56: =IF(ISNUMBER($B56),Aug2026_Live!$C$42+Aug2026_Live!$E$42*$B56,"") | H56: =IFERROR(IF(OR($G56="",Aug2026_Live!$C$93=""),"",1-NORMSDIST((Aug2026_Live!$C$41-$G56)/SQRT((Aug2026_Live!$E$42*Aug2026_Live!$C$93)^2+Aug2026_Live!$G$42^2))),"")
A58: Members loaded | B58: =COUNT($B$6:$B$56) -> 0
A59: Median member ERA5 | B59: =IFERROR(MEDIAN($B$6:$B$56),"")
A60: Min / Max member | B60: =IFERROR(MIN($B$6:$B$56),"") -> 0 | C60: =IFERROR(MAX($B$6:$B$56),"") -> 0
A61: Member spread σ (measured) | B61: =IFERROR(STDEV($B$6:$B$56),"")
A62: Members whose CENTRAL path breaks the record | B62: =IFERROR(SUM($F$6:$F$56),"") -> 0
A64: P(YES) ENSEMBLE — NOAA ▶ headline | E64: =IFERROR(AVERAGE($E$6:$E$56),"") | G64: P(YES) GISTEMP ▶ | H64: =IFERROR(AVERAGE($H$6:$H$56),"")
A66: Member-average of per-member tail probabilities — NOT the tail of the average (Jensen: the threshold tail is convex, so averaging probabilities > probability at the average).

Sheet Fcst_log
A1: FORECAST-RUN LOG — when a surge ENTERS the model (the lead-time edge)
A2: The fundamental leads the market price by ~2–3 days (July 2026: surge entered the 15 Jul 11:40Z run; price spiked 18 Jul).
A3: USE: a RISING remaining-days mean here = early BUY-YES signal before the tape moves. A price spike with NO new high here = FADE signal (liquidity vacuum, not information).
A5: Pulled (UTC) | B5: Model | C5: Run cycle | D5: Remaining-days mean anomaly °C | E5: Δ vs prior same model | F5: Signal | G5: Note
F6: =IF($E6="","",IF($E6>0.03,"▲ SURGE ENTERING — early YES signal",IF($E6<-0.03,"▼ COOLING — NO side strengthens","flat")))
E7: =IF($D7="","",IFERROR($D7-LOOKUP(2,1/($B$6:$B6=$B7),$D$6:$D6),"")) | F7: =IF($E7="","",IF($E7>0.03,"▲ SURGE ENTERING — early YES signal",IF($E7<-0.03,"▼ COOLING — NO side strengthens","flat")))
E8: =IF($D8="","",IFERROR($D8-LOOKUP(2,1/($B$6:$B7=$B8),$D$6:$D7),"")) | F8: =IF($E8="","",IF($E8>0.03,"▲ SURGE ENTERING — early YES signal",IF($E8<-0.03,"▼ COOLING — NO side strengthens","flat")))
E9: =IF($D9="","",IFERROR($D9-LOOKUP(2,1/($B$6:$B8=$B9),$D$6:$D8),"")) | F9: =IF($E9="","",IF($E9>0.03,"▲ SURGE ENTERING — early YES signal",IF($E9<-0.03,"▼ COOLING — NO side strengthens","flat")))
E10: =IF($D10="","",IFERROR($D10-LOOKUP(2,1/($B$6:$B9=$B10),$D$6:$D9),"")) | F10: =IF($E10="","",IF($E10>0.03,"▲ SURGE ENTERING — early YES signal",IF($E10<-0.03,"▼ COOLING — NO side strengthens","flat")))
E11: =IF($D11="","",IFERROR($D11-LOOKUP(2,1/($B$6:$B10=$B11),$D$6:$D10),"")) | F11: =IF($E11="","",IF($E11>0.03,"▲ SURGE ENTERING — early YES signal",IF($E11<-0.03,"▼ COOLING — NO side strengthens","flat")))
E12: =IF($D12="","",IFERROR($D12-LOOKUP(2,1/($B$6:$B11=$B12),$D$6:$D11),"")) | F12: =IF($E12="","",IF($E12>0.03,"▲ SURGE ENTERING — early YES signal",IF($E12<-0.03,"▼ COOLING — NO side strengthens","flat")))
E13: =IF($D13="","",IFERROR($D13-LOOKUP(2,1/($B$6:$B12=$B13),$D$6:$D12),"")) | F13: =IF($E13="","",IF($E13>0.03,"▲ SURGE ENTERING — early YES signal",IF($E13<-0.03,"▼ COOLING — NO side strengthens","flat")))
E14: =IF($D14="","",IFERROR($D14-LOOKUP(2,1/($B$6:$B13=$B14),$D$6:$D13),"")) | F14: =IF($E14="","",IF($E14>0.03,"▲ SURGE ENTERING — early YES signal",IF($E14<-0.03,"▼ COOLING — NO side strengthens","flat")))
E15: =IF($D15="","",IFERROR($D15-LOOKUP(2,1/($B$6:$B14=$B15),$D$6:$D14),"")) | F15: =IF($E15="","",IF($E15>0.03,"▲ SURGE ENTERING — early YES signal",IF($E15<-0.03,"▼ COOLING — NO side strengthens","flat")))
E16: =IF($D16="","",IFERROR($D16-LOOKUP(2,1/($B$6:$B15=$B16),$D$6:$D15),"")) | F16: =IF($E16="","",IF($E16>0.03,"▲ SURGE ENTERING — early YES signal",IF($E16<-0.03,"▼ COOLING — NO side strengthens","flat")))
E17: =IF($D17="","",IFERROR($D17-LOOKUP(2,1/($B$6:$B16=$B17),$D$6:$D16),"")) | F17: =IF($E17="","",IF($E17>0.03,"▲ SURGE ENTERING — early YES signal",IF($E17<-0.03,"▼ COOLING — NO side strengthens","flat")))
E18: =IF($D18="","",IFERROR($D18-LOOKUP(2,1/($B$6:$B17=$B18),$D$6:$D17),"")) | F18: =IF($E18="","",IF($E18>0.03,"▲ SURGE ENTERING — early YES signal",IF($E18<-0.03,"▼ COOLING — NO side strengthens","flat")))
... E125: =IF($D125="","",IFERROR($D125-LOOKUP(2,1/($B$6:$B124=$B125),$D$6:$D124),"")) | F125: =IF($E125="","",IF($E125>0.03,"▲ SURGE ENTERING — early YES signal",IF($E125<-0.03,"▼ COOLING — NO side strengthens","flat")))
