Workbook

Sheet Jun_2026
A1: KXHMONTH-26JUN — “Will June 2026 be the hottest June ever?”
A2: Settlement thresholds | E2: Variance σ_NOAA | K2: ENSEMBLE AVERAGE
A3: June record (printed) | C3: 1.18 | D3: June 2024 (NOAA). This record STOOD. | E3: k (observed days) | G3: sd_f (ERA5 scale) | H3: ref (offline) | I3: σ_NOAA | K3: ENSEMBLE HOTTEST
A4: Latent threshold (YES iff latent ≥) | C4: 1.185 | D4: Printed had to be ≥1.19. It printed 1.09 — never close. | E4: 2 | G4: =IFERROR(INDEX(LINEST($B$102:$B$118,$E$102:$F$118),3,2),$H$4) -> 0.0738 | H4: 0.0738 | I4: =IFERROR(SQRT(($C$6*$G$4)^2+$C$7^2),"") -> 0.068763395 | K4: ENSEMBLE COLDEST
A5: a (intercept) | C5: =INTERCEPT($C$102:$C$118,$B$102:$B$118) -> 0.62637623 | D5: formula: INTERCEPT(NOAA_Jun, ERA5_Jun) | E5: 10 | G5: =IFERROR(INDEX(LINEST($B$102:$B$118,$I$102:$J$118),3,2),$H$5) -> 0.0535 | H5: 0.0535 | I5: =IFERROR(SQRT(($C$6*$G$5)^2+$C$7^2),"") -> 0.054939087 | K5: ENSEMBLE PROBABILITY
A6: b (slope) | C6: =SLOPE($C$102:$C$118,$B$102:$B$118) -> 0.81348338 | E6: 15 | G6: =IFERROR(INDEX(LINEST($B$102:$B$118,$K$102:$L$118),3,2),$H$6) -> 0.0387 | H6: 0.0387 | I6: =IFERROR(SQRT(($C$6*$G$6)^2+$C$7^2),"") -> 0.045992376
A7: σ_translation (residual) | C7: =STEYX($C$102:$C$118,$B$102:$B$118) -> 0.03352901 | E7: 20 | G7: =IFERROR(INDEX(LINEST($B$102:$B$118,$M$102:$N$118),3,2),$H$7) -> 0.0271 | H7: 0.0271 | I7: =IFERROR(SQRT(($C$6*$G$7)^2+$C$7^2),"") -> 0.040127224
A8: n (years in fit) | C8: =COUNT($B$102:$B$118) -> 17 | E8: 25 | G8: =IFERROR(INDEX(LINEST($B$102:$B$118,$O$104:$P$118),3,2),$H$8) -> 0.0152 | H8: 0.0152 | I8: =IFERROR(SQRT(($C$6*$G$8)^2+$C$7^2),"") -> 0.035736346
A9: K_threshold on ERA5 scale = (latent−a)/b | C9: =($C$4-$C$5)/$C$6 -> 0.68670582 | E9: 30 | G9: 0 | H9: 0 | I9: =IFERROR(SQRT(($C$6*$G$9)^2+$C$7^2),"") -> 0.03352901
A10: External indices & model settings
A11: ONI (CPC, AMJ 2026) | C11: 1 | D11: El Niño ramping through the June window.
A12: GISTEMP June record (printed) | C12: 1.24 | D12: NASA GISTEMP — Polymarket oracle
A13: GISTEMP latent threshold | C13: 1.235 | D13: Polymarket brackets: ties count INTO the bracket.
A14: GISTEMP a / b / σ | C14: 0.5839 | D14: 0.9482 | F14: 0.0474 | H14: OLS GISTEMP_Jun ~ ERA5_Jun, n=36.
A16: ρ forecast-error correlation mix | C16: 0.6 | D16: CHANGW
A17: Climatology reference (5-yr mean ERA5 June) | C17: =AVERAGE($B$114:$B$118) -> 0.44098 | D17: CHANGE
A18: BLOCK 2 — DAILY TABLE (Jun 1–30)
A19: Date | B19: ERA5 obs anomaly °C | C19: ECMWF arch. mean °C | D19: ENS spread σ °C | E19: YES close (¢) | F19: Volume | G19: GEFS | H19: USED (obs→fcst) | I19: Running MTD (banked) | J19: Err ENS (obs−fcst) | K19: Err GFS | L19: Err GEFS | M19: |e|ENS | N19: e²ENS | O19: |e|GFS | P19: e²GFS | Q19: |e|GEFS | R19: e²GEFS | S19: (obs−clim)² | T19: ENS σ remaining | U19: 51-MEMBER ENSEMBLE | V19: Jun ERA5 mean °C | W19: μ_NOAA | X19: σ_member | Y19: P(YES) member | AA19: μ_GISTEMP | AB19: P(YES) GIS member
A20: May 28 | B20: 0.536 | C20: 0.6625 | E20: 10 | F20: 51 | H20: =IF(ISNUMBER($B20),$B20,IF(ISNUMBER($C20),$C20,"")) -> 0.536 | I20: =IF(COUNT($B$20:$B20)=0,"",AVERAGE($B$20:$B20)) -> 0.536 | J20: =IF(AND(ISNUMBER($B20),ISNUMBER($C20)),$B20-$C20,"") -> -0.1265 | K20: =IF(AND(ISNUMBER($B20),ISNUMBER(#REF!)),$B20-#REF!,"") | L20: =IF(AND(ISNUMBER($B20),ISNUMBER(#REF!)),$B20-#REF!,"") | M20: =IF(ISNUMBER($J20),ABS($J20),"") -> 0.1265 | N20: =IF(ISNUMBER($J20),$J20^2,"") -> 0.01600225 | O20: =IF(ISNUMBER($K20),ABS($K20),"") | P20: =IF(ISNUMBER($K20),$K20^2,"") | Q20: =IF(ISNUMBER($L20),ABS($L20),"") | R20: =IF(ISNUMBER($L20),$L20^2,"") | S20: =IF(ISNUMBER($B20),($B20-$C$17)^2,"") -> 0.0090288004 | T20: =IF(AND($B20="",ISNUMBER($D20)),$D20,"") | U20: 1 | V20: 0.5593 | W20: =IF(ISNUMBER($V20),Jun_2026!$C$5+Jun_2026!$C$6*$V20,"") -> 1.0813575 | X20: =IF(ISNUMBER($V20),IFERROR(SQRT((Jun_2026!$C$6*Jun_2026!$C$74)^2+Jun_2026!$C$7^2),""),"") -> 0.03352901 | Y20: =IF(OR($W20="",$X20="",$X20=0),"",1-NORMSDIST((Jun_2026!$C$4-$W20)/$X20)) -> 0.00099698246 | Z20: =IF(ISNUMBER($V20),IF($V20>=Jun_2026!$C$9,1,0),"") -> 0 | AA20: =IF(ISNUMBER($V20),Jun_2026!$C$14+Jun_2026!$D$14*$V20,"") -> 1.1142283 | AB20: =IFERROR(IF(OR($AA20="",Jun_2026!$C$74=""),"",1-NORMSDIST((Jun_2026!$C$13-$AA20)/SQRT((Jun_2026!$D$14*Jun_2026!$C$74)^2+Jun_2026!$F$14^2))),"") -> 0.0054182572
A21: May 29 | B21: 0.567 | C21: 0.7454 | E21: 10 | F21: 10 | H21: =IF(ISNUMBER($B21),$B21,IF(ISNUMBER($C21),$C21,"")) -> 0.567 | I21: =IF(COUNT($B$20:$B21)=0,"",AVERAGE($B$20:$B21)) -> 0.5515 | J21: =IF(AND(ISNUMBER($B21),ISNUMBER($C21)),$B21-$C21,"") -> -0.1784 | K21: =IF(AND(ISNUMBER($B21),ISNUMBER(#REF!)),$B21-#REF!,"") | L21: =IF(AND(ISNUMBER($B21),ISNUMBER(#REF!)),$B21-#REF!,"") | M21: =IF(ISNUMBER($J21),ABS($J21),"") -> 0.1784 | N21: =IF(ISNUMBER($J21),$J21^2,"") -> 0.03182656 | O21: =IF(ISNUMBER($K21),ABS($K21),"") | P21: =IF(ISNUMBER($K21),$K21^2,"") | Q21: =IF(ISNUMBER($L21),ABS($L21),"") | R21: =IF(ISNUMBER($L21),$L21^2,"") | S21: =IF(ISNUMBER($B21),($B21-$C$17)^2,"") -> 0.01588104 | T21: =IF(AND($B21="",ISNUMBER($D21)),$D21,"") | U21: 2 | V21: 0.5593 | W21: =IF(ISNUMBER($V21),Jun_2026!$C$5+Jun_2026!$C$6*$V21,"") -> 1.0813575 | X21: =IF(ISNUMBER($V21),IFERROR(SQRT((Jun_2026!$C$6*Jun_2026!$C$74)^2+Jun_2026!$C$7^2),""),"") -> 0.03352901 | Y21: =IF(OR($W21="",$X21="",$X21=0),"",1-NORMSDIST((Jun_2026!$C$4-$W21)/$X21)) -> 0.00099698246 | Z21: =IF(ISNUMBER($V21),IF($V21>=Jun_2026!$C$9,1,0),"") -> 0 | AA21: =IF(ISNUMBER($V21),Jun_2026!$C$14+Jun_2026!$D$14*$V21,"") -> 1.1142283 | AB21: =IFERROR(IF(OR($AA21="",Jun_2026!$C$74=""),"",1-NORMSDIST((Jun_2026!$C$13-$AA21)/SQRT((Jun_2026!$D$14*Jun_2026!$C$74)^2+Jun_2026!$F$14^2))),"") -> 0.0054182572
A22: May 30 | B22: 0.608 | C22: 0.687 | E22: 28 | F22: 1003.06 | H22: =IF(ISNUMBER($B22),$B22,IF(ISNUMBER($C22),$C22,"")) -> 0.608 | I22: =IF(COUNT($B$20:$B22)=0,"",AVERAGE($B$20:$B22)) -> 0.57033333 | J22: =IF(AND(ISNUMBER($B22),ISNUMBER($C22)),$B22-$C22,"") -> -0.079 | K22: =IF(AND(ISNUMBER($B22),ISNUMBER(#REF!)),$B22-#REF!,"") | L22: =IF(AND(ISNUMBER($B22),ISNUMBER(#REF!)),$B22-#REF!,"") | M22: =IF(ISNUMBER($J22),ABS($J22),"") -> 0.079 | N22: =IF(ISNUMBER($J22),$J22^2,"") -> 0.006241 | O22: =IF(ISNUMBER($K22),ABS($K22),"") | P22: =IF(ISNUMBER($K22),$K22^2,"") | Q22: =IF(ISNUMBER($L22),ABS($L22),"") | R22: =IF(ISNUMBER($L22),$L22^2,"") | S22: =IF(ISNUMBER($B22),($B22-$C$17)^2,"") -> 0.02789568 | T22: =IF(AND($B22="",ISNUMBER($D22)),$D22,"") | U22: 3 | V22: 0.5593 | W22: =IF(ISNUMBER($V22),Jun_2026!$C$5+Jun_2026!$C$6*$V22,"") -> 1.0813575 | X22: =IF(ISNUMBER($V22),IFERROR(SQRT((Jun_2026!$C$6*Jun_2026!$C$74)^2+Jun_2026!$C$7^2),""),"") -> 0.03352901 | Y22: =IF(OR($W22="",$X22="",$X22=0),"",1-NORMSDIST((Jun_2026!$C$4-$W22)/$X22)) -> 0.00099698246 | Z22: =IF(ISNUMBER($V22),IF($V22>=Jun_2026!$C$9,1,0),"") -> 0 | AA22: =IF(ISNUMBER($V22),Jun_2026!$C$14+Jun_2026!$D$14*$V22,"") -> 1.1142283 | AB22: =IFERROR(IF(OR($AA22="",Jun_2026!$C$74=""),"",1-NORMSDIST((Jun_2026!$C$13-$AA22)/SQRT((Jun_2026!$D$14*Jun_2026!$C$74)^2+Jun_2026!$F$14^2))),"") -> 0.0054182572
A23: May 31 | B23: 0.611 | C23: 0.5874 | E23: 21 | F23: 285.61 | H23: =IF(ISNUMBER($B23),$B23,IF(ISNUMBER($C23),$C23,"")) -> 0.611 | I23: =IF(COUNT($B$20:$B23)=0,"",AVERAGE($B$20:$B23)) -> 0.5805 | J23: =IF(AND(ISNUMBER($B23),ISNUMBER($C23)),$B23-$C23,"") -> 0.0236 | K23: =IF(AND(ISNUMBER($B23),ISNUMBER(#REF!)),$B23-#REF!,"") | L23: =IF(AND(ISNUMBER($B23),ISNUMBER(#REF!)),$B23-#REF!,"") | M23: =IF(ISNUMBER($J23),ABS($J23),"") -> 0.0236 | N23: =IF(ISNUMBER($J23),$J23^2,"") -> 0.00055696 | O23: =IF(ISNUMBER($K23),ABS($K23),"") | P23: =IF(ISNUMBER($K23),$K23^2,"") | Q23: =IF(ISNUMBER($L23),ABS($L23),"") | R23: =IF(ISNUMBER($L23),$L23^2,"") | S23: =IF(ISNUMBER($B23),($B23-$C$17)^2,"") -> 0.0289068 | T23: =IF(AND($B23="",ISNUMBER($D23)),$D23,"") | U23: 4 | V23: 0.5593 | W23: =IF(ISNUMBER($V23),Jun_2026!$C$5+Jun_2026!$C$6*$V23,"") -> 1.0813575 | X23: =IF(ISNUMBER($V23),IFERROR(SQRT((Jun_2026!$C$6*Jun_2026!$C$74)^2+Jun_2026!$C$7^2),""),"") -> 0.03352901 | Y23: =IF(OR($W23="",$X23="",$X23=0),"",1-NORMSDIST((Jun_2026!$C$4-$W23)/$X23)) -> 0.00099698246 | Z23: =IF(ISNUMBER($V23),IF($V23>=Jun_2026!$C$9,1,0),"") -> 0 | AA23: =IF(ISNUMBER($V23),Jun_2026!$C$14+Jun_2026!$D$14*$V23,"") -> 1.1142283 | AB23: =IFERROR(IF(OR($AA23="",Jun_2026!$C$74=""),"",1-NORMSDIST((Jun_2026!$C$13-$AA23)/SQRT((Jun_2026!$D$14*Jun_2026!$C$74)^2+Jun_2026!$F$14^2))),"") -> 0.0054182572
A24: Jun 01 | B24: 0.605 | C24: 0.6847 | E24: 15 | F24: 302.5 | H24: =IF(ISNUMBER($B24),$B24,IF(ISNUMBER($C24),$C24,"")) -> 0.605 | I24: =IF(COUNT($B$20:$B24)=0,"",AVERAGE($B$20:$B24)) -> 0.5854 | J24: =IF(AND(ISNUMBER($B24),ISNUMBER($C24)),$B24-$C24,"") -> -0.0797 | K24: =IF(AND(ISNUMBER($B24),ISNUMBER(#REF!)),$B24-#REF!,"") | L24: =IF(AND(ISNUMBER($B24),ISNUMBER(#REF!)),$B24-#REF!,"") | M24: =IF(ISNUMBER($J24),ABS($J24),"") -> 0.0797 | N24: =IF(ISNUMBER($J24),$J24^2,"") -> 0.00635209 | O24: =IF(ISNUMBER($K24),ABS($K24),"") | P24: =IF(ISNUMBER($K24),$K24^2,"") | Q24: =IF(ISNUMBER($L24),ABS($L24),"") | R24: =IF(ISNUMBER($L24),$L24^2,"") | S24: =IF(ISNUMBER($B24),($B24-$C$17)^2,"") -> 0.02690256 | T24: =IF(AND($B24="",ISNUMBER($D24)),$D24,"") | U24: 5 | V24: 0.5593 | W24: =IF(ISNUMBER($V24),Jun_2026!$C$5+Jun_2026!$C$6*$V24,"") -> 1.0813575 | X24: =IF(ISNUMBER($V24),IFERROR(SQRT((Jun_2026!$C$6*Jun_2026!$C$74)^2+Jun_2026!$C$7^2),""),"") -> 0.03352901 | Y24: =IF(OR($W24="",$X24="",$X24=0),"",1-NORMSDIST((Jun_2026!$C$4-$W24)/$X24)) -> 0.00099698246 | Z24: =IF(ISNUMBER($V24),IF($V24>=Jun_2026!$C$9,1,0),"") -> 0 | AA24: =IF(ISNUMBER($V24),Jun_2026!$C$14+Jun_2026!$D$14*$V24,"") -> 1.1142283 | AB24: =IFERROR(IF(OR($AA24="",Jun_2026!$C$74=""),"",1-NORMSDIST((Jun_2026!$C$13-$AA24)/SQRT((Jun_2026!$D$14*Jun_2026!$C$74)^2+Jun_2026!$F$14^2))),"") -> 0.0054182572
A25: Jun 02 | B25: 0.651 | C25: 0.7047 | E25: 13 | F25: 240.81 | H25: =IF(ISNUMBER($B25),$B25,IF(ISNUMBER($C25),$C25,"")) -> 0.651 | I25: =IF(COUNT($B$20:$B25)=0,"",AVERAGE($B$20:$B25)) -> 0.59633333 | J25: =IF(AND(ISNUMBER($B25),ISNUMBER($C25)),$B25-$C25,"") -> -0.0537 | K25: =IF(AND(ISNUMBER($B25),ISNUMBER(#REF!)),$B25-#REF!,"") | L25: =IF(AND(ISNUMBER($B25),ISNUMBER(#REF!)),$B25-#REF!,"") | M25: =IF(ISNUMBER($J25),ABS($J25),"") -> 0.0537 | N25: =IF(ISNUMBER($J25),$J25^2,"") -> 0.00288369 | O25: =IF(ISNUMBER($K25),ABS($K25),"") | P25: =IF(ISNUMBER($K25),$K25^2,"") | Q25: =IF(ISNUMBER($L25),ABS($L25),"") | R25: =IF(ISNUMBER($L25),$L25^2,"") | S25: =IF(ISNUMBER($B25),($B25-$C$17)^2,"") -> 0.0441084 | T25: =IF(AND($B25="",ISNUMBER($D25)),$D25,"") | U25: 6 | V25: 0.5593 | W25: =IF(ISNUMBER($V25),Jun_2026!$C$5+Jun_2026!$C$6*$V25,"") -> 1.0813575 | X25: =IF(ISNUMBER($V25),IFERROR(SQRT((Jun_2026!$C$6*Jun_2026!$C$74)^2+Jun_2026!$C$7^2),""),"") -> 0.03352901 | Y25: =IF(OR($W25="",$X25="",$X25=0),"",1-NORMSDIST((Jun_2026!$C$4-$W25)/$X25)) -> 0.00099698246 | Z25: =IF(ISNUMBER($V25),IF($V25>=Jun_2026!$C$9,1,0),"") -> 0 | AA25: =IF(ISNUMBER($V25),Jun_2026!$C$14+Jun_2026!$D$14*$V25,"") -> 1.1142283 | AB25: =IFERROR(IF(OR($AA25="",Jun_2026!$C$74=""),"",1-NORMSDIST((Jun_2026!$C$13-$AA25)/SQRT((Jun_2026!$D$14*Jun_2026!$C$74)^2+Jun_2026!$F$14^2))),"") -> 0.0054182572
A26: Jun 03 | B26: 0.653 | C26: 0.8007 | E26: 13 | F26: 21 | H26: =IF(ISNUMBER($B26),$B26,IF(ISNUMBER($C26),$C26,"")) -> 0.653 | I26: =IF(COUNT($B$20:$B26)=0,"",AVERAGE($B$20:$B26)) -> 0.60442857 | J26: =IF(AND(ISNUMBER($B26),ISNUMBER($C26)),$B26-$C26,"") -> -0.1477 | K26: =IF(AND(ISNUMBER($B26),ISNUMBER(#REF!)),$B26-#REF!,"") | L26: =IF(AND(ISNUMBER($B26),ISNUMBER(#REF!)),$B26-#REF!,"") | M26: =IF(ISNUMBER($J26),ABS($J26),"") -> 0.1477 | N26: =IF(ISNUMBER($J26),$J26^2,"") -> 0.02181529 | O26: =IF(ISNUMBER($K26),ABS($K26),"") | P26: =IF(ISNUMBER($K26),$K26^2,"") | Q26: =IF(ISNUMBER($L26),ABS($L26),"") | R26: =IF(ISNUMBER($L26),$L26^2,"") | S26: =IF(ISNUMBER($B26),($B26-$C$17)^2,"") -> 0.04495248 | T26: =IF(AND($B26="",ISNUMBER($D26)),$D26,"") | U26: 7 | V26: 0.5593 | W26: =IF(ISNUMBER($V26),Jun_2026!$C$5+Jun_2026!$C$6*$V26,"") -> 1.0813575 | X26: =IF(ISNUMBER($V26),IFERROR(SQRT((Jun_2026!$C$6*Jun_2026!$C$74)^2+Jun_2026!$C$7^2),""),"") -> 0.03352901 | Y26: =IF(OR($W26="",$X26="",$X26=0),"",1-NORMSDIST((Jun_2026!$C$4-$W26)/$X26)) -> 0.00099698246 | Z26: =IF(ISNUMBER($V26),IF($V26>=Jun_2026!$C$9,1,0),"") -> 0 | AA26: =IF(ISNUMBER($V26),Jun_2026!$C$14+Jun_2026!$D$14*$V26,"") -> 1.1142283 | AB26: =IFERROR(IF(OR($AA26="",Jun_2026!$C$74=""),"",1-NORMSDIST((Jun_2026!$C$13-$AA26)/SQRT((Jun_2026!$D$14*Jun_2026!$C$74)^2+Jun_2026!$F$14^2))),"") -> 0.0054182572
A27: Jun 04 | B27: 0.646 | C27: 0.7268 | E27: 15 | F27: 27.22 | H27: =IF(ISNUMBER($B27),$B27,IF(ISNUMBER($C27),$C27,"")) -> 0.646 | I27: =IF(COUNT($B$20:$B27)=0,"",AVERAGE($B$20:$B27)) -> 0.609625 | J27: =IF(AND(ISNUMBER($B27),ISNUMBER($C27)),$B27-$C27,"") -> -0.0808 | K27: =IF(AND(ISNUMBER($B27),ISNUMBER(#REF!)),$B27-#REF!,"") | L27: =IF(AND(ISNUMBER($B27),ISNUMBER(#REF!)),$B27-#REF!,"") | M27: =IF(ISNUMBER($J27),ABS($J27),"") -> 0.0808 | N27: =IF(ISNUMBER($J27),$J27^2,"") -> 0.00652864 | O27: =IF(ISNUMBER($K27),ABS($K27),"") | P27: =IF(ISNUMBER($K27),$K27^2,"") | Q27: =IF(ISNUMBER($L27),ABS($L27),"") | R27: =IF(ISNUMBER($L27),$L27^2,"") | S27: =IF(ISNUMBER($B27),($B27-$C$17)^2,"") -> 0.0420332 | T27: =IF(AND($B27="",ISNUMBER($D27)),$D27,"") | U27: 8 | V27: 0.5593 | W27: =IF(ISNUMBER($V27),Jun_2026!$C$5+Jun_2026!$C$6*$V27,"") -> 1.0813575 | X27: =IF(ISNUMBER($V27),IFERROR(SQRT((Jun_2026!$C$6*Jun_2026!$C$74)^2+Jun_2026!$C$7^2),""),"") -> 0.03352901 | Y27: =IF(OR($W27="",$X27="",$X27=0),"",1-NORMSDIST((Jun_2026!$C$4-$W27)/$X27)) -> 0.00099698246 | Z27: =IF(ISNUMBER($V27),IF($V27>=Jun_2026!$C$9,1,0),"") -> 0 | AA27: =IF(ISNUMBER($V27),Jun_2026!$C$14+Jun_2026!$D$14*$V27,"") -> 1.1142283 | AB27: =IFERROR(IF(OR($AA27="",Jun_2026!$C$74=""),"",1-NORMSDIST((Jun_2026!$C$13-$AA27)/SQRT((Jun_2026!$D$14*Jun_2026!$C$74)^2+Jun_2026!$F$14^2))),"") -> 0.0054182572
A28: Jun 05 | B28: 0.607 | C28: 0.6995 | E28: 15 | F28: 720.73 | H28: =IF(ISNUMBER($B28),$B28,IF(ISNUMBER($C28),$C28,"")) -> 0.607 | I28: =IF(COUNT($B$20:$B28)=0,"",AVERAGE($B$20:$B28)) -> 0.60933333 | J28: =IF(AND(ISNUMBER($B28),ISNUMBER($C28)),$B28-$C28,"") -> -0.0925 | K28: =IF(AND(ISNUMBER($B28),ISNUMBER(#REF!)),$B28-#REF!,"") | L28: =IF(AND(ISNUMBER($B28),ISNUMBER(#REF!)),$B28-#REF!,"") | M28: =IF(ISNUMBER($J28),ABS($J28),"") -> 0.0925 | N28: =IF(ISNUMBER($J28),$J28^2,"") -> 0.00855625 | O28: =IF(ISNUMBER($K28),ABS($K28),"") | P28: =IF(ISNUMBER($K28),$K28^2,"") | Q28: =IF(ISNUMBER($L28),ABS($L28),"") | R28: =IF(ISNUMBER($L28),$L28^2,"") | S28: =IF(ISNUMBER($B28),($B28-$C$17)^2,"") -> 0.02756264 | T28: =IF(AND($B28="",ISNUMBER($D28)),$D28,"") | U28: 9 | V28: 0.5593 | W28: =IF(ISNUMBER($V28),Jun_2026!$C$5+Jun_2026!$C$6*$V28,"") -> 1.0813575 | X28: =IF(ISNUMBER($V28),IFERROR(SQRT((Jun_2026!$C$6*Jun_2026!$C$74)^2+Jun_2026!$C$7^2),""),"") -> 0.03352901 | Y28: =IF(OR($W28="",$X28="",$X28=0),"",1-NORMSDIST((Jun_2026!$C$4-$W28)/$X28)) -> 0.00099698246 | Z28: =IF(ISNUMBER($V28),IF($V28>=Jun_2026!$C$9,1,0),"") -> 0 | AA28: =IF(ISNUMBER($V28),Jun_2026!$C$14+Jun_2026!$D$14*$V28,"") -> 1.1142283 | AB28: =IFERROR(IF(OR($AA28="",Jun_2026!$C$74=""),"",1-NORMSDIST((Jun_2026!$C$13-$AA28)/SQRT((Jun_2026!$D$14*Jun_2026!$C$74)^2+Jun_2026!$F$14^2))),"") -> 0.0054182572
A29: Jun 06 | B29: 0.596 | C29: 0.8535 | E29: 13 | F29: 280.5 | H29: =IF(ISNUMBER($B29),$B29,IF(ISNUMBER($C29),$C29,"")) -> 0.596 | I29: =IF(COUNT($B$20:$B29)=0,"",AVERAGE($B$20:$B29)) -> 0.608 | J29: =IF(AND(ISNUMBER($B29),ISNUMBER($C29)),$B29-$C29,"") -> -0.2575 | K29: =IF(AND(ISNUMBER($B29),ISNUMBER(#REF!)),$B29-#REF!,"") | L29: =IF(AND(ISNUMBER($B29),ISNUMBER(#REF!)),$B29-#REF!,"") | M29: =IF(ISNUMBER($J29),ABS($J29),"") -> 0.2575 | N29: =IF(ISNUMBER($J29),$J29^2,"") -> 0.06630625 | O29: =IF(ISNUMBER($K29),ABS($K29),"") | P29: =IF(ISNUMBER($K29),$K29^2,"") | Q29: =IF(ISNUMBER($L29),ABS($L29),"") | R29: =IF(ISNUMBER($L29),$L29^2,"") | S29: =IF(ISNUMBER($B29),($B29-$C$17)^2,"") -> 0.0240312 | T29: =IF(AND($B29="",ISNUMBER($D29)),$D29,"") | U29: 10 | V29: 0.5593 | W29: =IF(ISNUMBER($V29),Jun_2026!$C$5+Jun_2026!$C$6*$V29,"") -> 1.0813575 | X29: =IF(ISNUMBER($V29),IFERROR(SQRT((Jun_2026!$C$6*Jun_2026!$C$74)^2+Jun_2026!$C$7^2),""),"") -> 0.03352901 | Y29: =IF(OR($W29="",$X29="",$X29=0),"",1-NORMSDIST((Jun_2026!$C$4-$W29)/$X29)) -> 0.00099698246 | Z29: =IF(ISNUMBER($V29),IF($V29>=Jun_2026!$C$9,1,0),"") -> 0 | AA29: =IF(ISNUMBER($V29),Jun_2026!$C$14+Jun_2026!$D$14*$V29,"") -> 1.1142283 | AB29: =IFERROR(IF(OR($AA29="",Jun_2026!$C$74=""),"",1-NORMSDIST((Jun_2026!$C$13-$AA29)/SQRT((Jun_2026!$D$14*Jun_2026!$C$74)^2+Jun_2026!$F$14^2))),"") -> 0.0054182572
A30: Jun 07 | B30: 0.622 | C30: 0.7588 | E30: 12 | F30: 296.2 | H30: =IF(ISNUMBER($B30),$B30,IF(ISNUMBER($C30),$C30,"")) -> 0.622 | I30: =IF(COUNT($B$20:$B30)=0,"",AVERAGE($B$20:$B30)) -> 0.60927273 | J30: =IF(AND(ISNUMBER($B30),ISNUMBER($C30)),$B30-$C30,"") -> -0.1368 | K30: =IF(AND(ISNUMBER($B30),ISNUMBER(#REF!)),$B30-#REF!,"") | L30: =IF(AND(ISNUMBER($B30),ISNUMBER(#REF!)),$B30-#REF!,"") | M30: =IF(ISNUMBER($J30),ABS($J30),"") -> 0.1368 | N30: =IF(ISNUMBER($J30),$J30^2,"") -> 0.01871424 | O30: =IF(ISNUMBER($K30),ABS($K30),"") | P30: =IF(ISNUMBER($K30),$K30^2,"") | Q30: =IF(ISNUMBER($L30),ABS($L30),"") | R30: =IF(ISNUMBER($L30),$L30^2,"") | S30: =IF(ISNUMBER($B30),($B30-$C$17)^2,"") -> 0.03276824 | T30: =IF(AND($B30="",ISNUMBER($D30)),$D30,"") | U30: 11 | V30: 0.5593 | W30: =IF(ISNUMBER($V30),Jun_2026!$C$5+Jun_2026!$C$6*$V30,"") -> 1.0813575 | X30: =IF(ISNUMBER($V30),IFERROR(SQRT((Jun_2026!$C$6*Jun_2026!$C$74)^2+Jun_2026!$C$7^2),""),"") -> 0.03352901 | Y30: =IF(OR($W30="",$X30="",$X30=0),"",1-NORMSDIST((Jun_2026!$C$4-$W30)/$X30)) -> 0.00099698246 | Z30: =IF(ISNUMBER($V30),IF($V30>=Jun_2026!$C$9,1,0),"") -> 0 | AA30: =IF(ISNUMBER($V30),Jun_2026!$C$14+Jun_2026!$D$14*$V30,"") -> 1.1142283 | AB30: =IFERROR(IF(OR($AA30="",Jun_2026!$C$74=""),"",1-NORMSDIST((Jun_2026!$C$13-$AA30)/SQRT((Jun_2026!$D$14*Jun_2026!$C$74)^2+Jun_2026!$F$14^2))),"") -> 0.0054182572
A31: Jun 08 | B31: 0.6 | C31: 0.7158 | E31: 10 | F31: 15.9 | H31: =IF(ISNUMBER($B31),$B31,IF(ISNUMBER($C31),$C31,"")) -> 0.6 | I31: =IF(COUNT($B$20:$B31)=0,"",AVERAGE($B$20:$B31)) -> 0.6085 | J31: =IF(AND(ISNUMBER($B31),ISNUMBER($C31)),$B31-$C31,"") -> -0.1158 | K31: =IF(AND(ISNUMBER($B31),ISNUMBER(#REF!)),$B31-#REF!,"") | L31: =IF(AND(ISNUMBER($B31),ISNUMBER(#REF!)),$B31-#REF!,"") | M31: =IF(ISNUMBER($J31),ABS($J31),"") -> 0.1158 | N31: =IF(ISNUMBER($J31),$J31^2,"") -> 0.01340964 | O31: =IF(ISNUMBER($K31),ABS($K31),"") | P31: =IF(ISNUMBER($K31),$K31^2,"") | Q31: =IF(ISNUMBER($L31),ABS($L31),"") | R31: =IF(ISNUMBER($L31),$L31^2,"") | S31: =IF(ISNUMBER($B31),($B31-$C$17)^2,"") -> 0.02528736 | T31: =IF(AND($B31="",ISNUMBER($D31)),$D31,"") | U31: 12 | V31: 0.5593 | W31: =IF(ISNUMBER($V31),Jun_2026!$C$5+Jun_2026!$C$6*$V31,"") -> 1.0813575 | X31: =IF(ISNUMBER($V31),IFERROR(SQRT((Jun_2026!$C$6*Jun_2026!$C$74)^2+Jun_2026!$C$7^2),""),"") -> 0.03352901 | Y31: =IF(OR($W31="",$X31="",$X31=0),"",1-NORMSDIST((Jun_2026!$C$4-$W31)/$X31)) -> 0.00099698246 | Z31: =IF(ISNUMBER($V31),IF($V31>=Jun_2026!$C$9,1,0),"") -> 0 | AA31: =IF(ISNUMBER($V31),Jun_2026!$C$14+Jun_2026!$D$14*$V31,"") -> 1.1142283 | AB31: =IFERROR(IF(OR($AA31="",Jun_2026!$C$74=""),"",1-NORMSDIST((Jun_2026!$C$13-$AA31)/SQRT((Jun_2026!$D$14*Jun_2026!$C$74)^2+Jun_2026!$F$14^2))),"") -> 0.0054182572
... A49: Jun 26 | B49: 0.635 | C49: 0.6909 | E49: 4 | F49: 1797.72 | H49: =IF(ISNUMBER($B49),$B49,IF(ISNUMBER($C49),$C49,"")) -> 0.635 | I49: =IF(COUNT($B$20:$B49)=0,"",AVERAGE($B$20:$B49)) -> 0.5593 | J49: =IF(AND(ISNUMBER($B49),ISNUMBER($C49)),$B49-$C49,"") -> -0.0559 | K49: =IF(AND(ISNUMBER($B49),ISNUMBER(#REF!)),$B49-#REF!,"") | L49: =IF(AND(ISNUMBER($B49),ISNUMBER(#REF!)),$B49-#REF!,"") | M49: =IF(ISNUMBER($J49),ABS($J49),"") -> 0.0559 | N49: =IF(ISNUMBER($J49),$J49^2,"") -> 0.00312481 | O49: =IF(ISNUMBER($K49),ABS($K49),"") | P49: =IF(ISNUMBER($K49),$K49^2,"") | Q49: =IF(ISNUMBER($L49),ABS($L49),"") | R49: =IF(ISNUMBER($L49),$L49^2,"") | S49: =IF(ISNUMBER($B49),($B49-$C$17)^2,"") -> 0.03764376 | T49: =IF(AND($B49="",ISNUMBER($D49)),$D49,"") | U49: 30 | V49: 0.5593 | W49: =IF(ISNUMBER($V49),Jun_2026!$C$5+Jun_2026!$C$6*$V49,"") -> 1.0813575 | X49: =IF(ISNUMBER($V49),IFERROR(SQRT((Jun_2026!$C$6*Jun_2026!$C$74)^2+Jun_2026!$C$7^2),""),"") -> 0.03352901 | Y49: =IF(OR($W49="",$X49="",$X49=0),"",1-NORMSDIST((Jun_2026!$C$4-$W49)/$X49)) -> 0.00099698246 | Z49: =IF(ISNUMBER($V49),IF($V49>=Jun_2026!$C$9,1,0),"") -> 0 | AA49: =IF(ISNUMBER($V49),Jun_2026!$C$14+Jun_2026!$D$14*$V49,"") -> 1.1142283 | AB49: =IFERROR(IF(OR($AA49="",Jun_2026!$C$74=""),"",1-NORMSDIST((Jun_2026!$C$13-$AA49)/SQRT((Jun_2026!$D$14*Jun_2026!$C$74)^2+Jun_2026!$F$14^2))),"") -> 0.0054182572
A50: Jun 27 | E50: 5 | F50: 2166.13 | U50: 31 | V50: 0.5593 | W50: =IF(ISNUMBER($V50),Jun_2026!$C$5+Jun_2026!$C$6*$V50,"") -> 1.0813575 | X50: =IF(ISNUMBER($V50),IFERROR(SQRT((Jun_2026!$C$6*Jun_2026!$C$74)^2+Jun_2026!$C$7^2),""),"") -> 0.03352901 | Y50: =IF(OR($W50="",$X50="",$X50=0),"",1-NORMSDIST((Jun_2026!$C$4-$W50)/$X50)) -> 0.00099698246 | Z50: =IF(ISNUMBER($V50),IF($V50>=Jun_2026!$C$9,1,0),"") -> 0 | AA50: =IF(ISNUMBER($V50),Jun_2026!$C$14+Jun_2026!$D$14*$V50,"") -> 1.1142283 | AB50: =IFERROR(IF(OR($AA50="",Jun_2026!$C$74=""),"",1-NORMSDIST((Jun_2026!$C$13-$AA50)/SQRT((Jun_2026!$D$14*Jun_2026!$C$74)^2+Jun_2026!$F$14^2))),"") -> 0.0054182572
A51: Jun 28 | E51: 5 | F51: 836.56 | U51: 32 | V51: 0.5593 | W51: =IF(ISNUMBER($V51),Jun_2026!$C$5+Jun_2026!$C$6*$V51,"") -> 1.0813575 | X51: =IF(ISNUMBER($V51),IFERROR(SQRT((Jun_2026!$C$6*Jun_2026!$C$74)^2+Jun_2026!$C$7^2),""),"") -> 0.03352901 | Y51: =IF(OR($W51="",$X51="",$X51=0),"",1-NORMSDIST((Jun_2026!$C$4-$W51)/$X51)) -> 0.00099698246 | Z51: =IF(ISNUMBER($V51),IF($V51>=Jun_2026!$C$9,1,0),"") -> 0 | AA51: =IF(ISNUMBER($V51),Jun_2026!$C$14+Jun_2026!$D$14*$V51,"") -> 1.1142283 | AB51: =IFERROR(IF(OR($AA51="",Jun_2026!$C$74=""),"",1-NORMSDIST((Jun_2026!$C$13-$AA51)/SQRT((Jun_2026!$D$14*Jun_2026!$C$74)^2+Jun_2026!$F$14^2))),"") -> 0.0054182572
A52: Jun 29 | E52: 6 | F52: 4397.78 | U52: 33 | V52: 0.5593 | W52: =IF(ISNUMBER($V52),Jun_2026!$C$5+Jun_2026!$C$6*$V52,"") -> 1.0813575 | X52: =IF(ISNUMBER($V52),IFERROR(SQRT((Jun_2026!$C$6*Jun_2026!$C$74)^2+Jun_2026!$C$7^2),""),"") -> 0.03352901 | Y52: =IF(OR($W52="",$X52="",$X52=0),"",1-NORMSDIST((Jun_2026!$C$4-$W52)/$X52)) -> 0.00099698246 | Z52: =IF(ISNUMBER($V52),IF($V52>=Jun_2026!$C$9,1,0),"") -> 0 | AA52: =IF(ISNUMBER($V52),Jun_2026!$C$14+Jun_2026!$D$14*$V52,"") -> 1.1142283 | AB52: =IFERROR(IF(OR($AA52="",Jun_2026!$C$74=""),"",1-NORMSDIST((Jun_2026!$C$13-$AA52)/SQRT((Jun_2026!$D$14*Jun_2026!$C$74)^2+Jun_2026!$F$14^2))),"") -> 0.0054182572
A53: Jun 30 | E53: 3 | F53: 1818.51 | U53: 34 | V53: 0.5593 | W53: =IF(ISNUMBER($V53),Jun_2026!$C$5+Jun_2026!$C$6*$V53,"") -> 1.0813575 | X53: =IF(ISNUMBER($V53),IFERROR(SQRT((Jun_2026!$C$6*Jun_2026!$C$74)^2+Jun_2026!$C$7^2),""),"") -> 0.03352901 | Y53: =IF(OR($W53="",$X53="",$X53=0),"",1-NORMSDIST((Jun_2026!$C$4-$W53)/$X53)) -> 0.00099698246 | Z53: =IF(ISNUMBER($V53),IF($V53>=Jun_2026!$C$9,1,0),"") -> 0 | AA53: =IF(ISNUMBER($V53),Jun_2026!$C$14+Jun_2026!$D$14*$V53,"") -> 1.1142283 | AB53: =IFERROR(IF(OR($AA53="",Jun_2026!$C$74=""),"",1-NORMSDIST((Jun_2026!$C$13-$AA53)/SQRT((Jun_2026!$D$14*Jun_2026!$C$74)^2+Jun_2026!$F$14^2))),"") -> 0.0054182572
A54: Jul 01 | E54: 3 | F54: 3601.23 | U54: 35 | V54: 0.5593 | W54: =IF(ISNUMBER($V54),Jun_2026!$C$5+Jun_2026!$C$6*$V54,"") -> 1.0813575 | X54: =IF(ISNUMBER($V54),IFERROR(SQRT((Jun_2026!$C$6*Jun_2026!$C$74)^2+Jun_2026!$C$7^2),""),"") -> 0.03352901 | Y54: =IF(OR($W54="",$X54="",$X54=0),"",1-NORMSDIST((Jun_2026!$C$4-$W54)/$X54)) -> 0.00099698246 | Z54: =IF(ISNUMBER($V54),IF($V54>=Jun_2026!$C$9,1,0),"") -> 0 | AA54: =IF(ISNUMBER($V54),Jun_2026!$C$14+Jun_2026!$D$14*$V54,"") -> 1.1142283 | AB54: =IFERROR(IF(OR($AA54="",Jun_2026!$C$74=""),"",1-NORMSDIST((Jun_2026!$C$13-$AA54)/SQRT((Jun_2026!$D$14*Jun_2026!$C$74)^2+Jun_2026!$F$14^2))),"") -> 0.0054182572
A55: Jul 02 | E55: 6 | F55: 9645.98 | U55: 36 | V55: 0.5593 | W55: =IF(ISNUMBER($V55),Jun_2026!$C$5+Jun_2026!$C$6*$V55,"") -> 1.0813575 | X55: =IF(ISNUMBER($V55),IFERROR(SQRT((Jun_2026!$C$6*Jun_2026!$C$74)^2+Jun_2026!$C$7^2),""),"") -> 0.03352901 | Y55: =IF(OR($W55="",$X55="",$X55=0),"",1-NORMSDIST((Jun_2026!$C$4-$W55)/$X55)) -> 0.00099698246 | Z55: =IF(ISNUMBER($V55),IF($V55>=Jun_2026!$C$9,1,0),"") -> 0 | AA55: =IF(ISNUMBER($V55),Jun_2026!$C$14+Jun_2026!$D$14*$V55,"") -> 1.1142283 | AB55: =IFERROR(IF(OR($AA55="",Jun_2026!$C$74=""),"",1-NORMSDIST((Jun_2026!$C$13-$AA55)/SQRT((Jun_2026!$D$14*Jun_2026!$C$74)^2+Jun_2026!$F$14^2))),"") -> 0.0054182572
A56: Jul 03 | E56: 9 | F56: 11630.15 | U56: 37 | V56: 0.5593 | W56: =IF(ISNUMBER($V56),Jun_2026!$C$5+Jun_2026!$C$6*$V56,"") -> 1.0813575 | X56: =IF(ISNUMBER($V56),IFERROR(SQRT((Jun_2026!$C$6*Jun_2026!$C$74)^2+Jun_2026!$C$7^2),""),"") -> 0.03352901 | Y56: =IF(OR($W56="",$X56="",$X56=0),"",1-NORMSDIST((Jun_2026!$C$4-$W56)/$X56)) -> 0.00099698246 | Z56: =IF(ISNUMBER($V56),IF($V56>=Jun_2026!$C$9,1,0),"") -> 0 | AA56: =IF(ISNUMBER($V56),Jun_2026!$C$14+Jun_2026!$D$14*$V56,"") -> 1.1142283 | AB56: =IFERROR(IF(OR($AA56="",Jun_2026!$C$74=""),"",1-NORMSDIST((Jun_2026!$C$13-$AA56)/SQRT((Jun_2026!$D$14*Jun_2026!$C$74)^2+Jun_2026!$F$14^2))),"") -> 0.0054182572
A57: Jul 04 | E57: 8 | F57: 7321.56 | U57: 38 | V57: 0.5593 | W57: =IF(ISNUMBER($V57),Jun_2026!$C$5+Jun_2026!$C$6*$V57,"") -> 1.0813575 | X57: =IF(ISNUMBER($V57),IFERROR(SQRT((Jun_2026!$C$6*Jun_2026!$C$74)^2+Jun_2026!$C$7^2),""),"") -> 0.03352901 | Y57: =IF(OR($W57="",$X57="",$X57=0),"",1-NORMSDIST((Jun_2026!$C$4-$W57)/$X57)) -> 0.00099698246 | Z57: =IF(ISNUMBER($V57),IF($V57>=Jun_2026!$C$9,1,0),"") -> 0 | AA57: =IF(ISNUMBER($V57),Jun_2026!$C$14+Jun_2026!$D$14*$V57,"") -> 1.1142283 | AB57: =IFERROR(IF(OR($AA57="",Jun_2026!$C$74=""),"",1-NORMSDIST((Jun_2026!$C$13-$AA57)/SQRT((Jun_2026!$D$14*Jun_2026!$C$74)^2+Jun_2026!$F$14^2))),"") -> 0.0054182572
A58: Jul 05 | E58: 10 | F58: 5582.72 | U58: 39 | V58: 0.5593 | W58: =IF(ISNUMBER($V58),Jun_2026!$C$5+Jun_2026!$C$6*$V58,"") -> 1.0813575 | X58: =IF(ISNUMBER($V58),IFERROR(SQRT((Jun_2026!$C$6*Jun_2026!$C$74)^2+Jun_2026!$C$7^2),""),"") -> 0.03352901 | Y58: =IF(OR($W58="",$X58="",$X58=0),"",1-NORMSDIST((Jun_2026!$C$4-$W58)/$X58)) -> 0.00099698246 | Z58: =IF(ISNUMBER($V58),IF($V58>=Jun_2026!$C$9,1,0),"") -> 0 | AA58: =IF(ISNUMBER($V58),Jun_2026!$C$14+Jun_2026!$D$14*$V58,"") -> 1.1142283 | AB58: =IFERROR(IF(OR($AA58="",Jun_2026!$C$74=""),"",1-NORMSDIST((Jun_2026!$C$13-$AA58)/SQRT((Jun_2026!$D$14*Jun_2026!$C$74)^2+Jun_2026!$F$14^2))),"") -> 0.0054182572
...

Sheet Jul_2026

Sheet Aug_2026

Sheet Sep_2026
